# --- Content from errors_2025-04-10.log ---
2025-04-10 19:35:02 | ERROR    | __main__:<module>:89 - This is an error message.
2025-04-10 19:35:02 | ERROR    | __main__:<module>:94 - Caught an exception!
Traceback (most recent call last):
  File "<frozen runpy>", line 198, in _run_module_as_main
  File "<frozen runpy>", line 88, in _run_code
> File "C:\DreamerAI\engine\core\logger.py", line 92, in <module>
    1 / 0
ZeroDivisionError: division by zero
Traceback (most recent call last):
  File "<frozen runpy>", line 198, in _run_module_as_main
  File "<frozen runpy>", line 88, in _run_code
> File "C:\DreamerAI\engine\core\logger.py", line 92, in <module>
    1 / 0
ZeroDivisionError: division by zero
2025-04-10 21:02:21 | ERROR    | __main__:<module>:89 - This is an error message.
2025-04-10 21:02:21 | ERROR    | __main__:<module>:94 - Caught an exception!
Traceback (most recent call last):
  File "<frozen runpy>", line 198, in _run_module_as_main
  File "<frozen runpy>", line 88, in _run_code
> File "C:\DreamerAI\engine\core\logger.py", line 92, in <module>
    1 / 0
ZeroDivisionError: division by zero
Traceback (most recent call last):
  File "<frozen runpy>", line 198, in _run_module_as_main
  File "<frozen runpy>", line 88, in _run_code
> File "C:\DreamerAI\engine\core\logger.py", line 92, in <module>
    1 / 0
ZeroDivisionError: division by zero
2025-04-10 21:54:31 | ERROR    | __main__:generate:283 - All configured providers failed to generate a response: ['ollama', 'cloud_tier1', 'cloud_tier2']
2025-04-10 21:54:31 | ERROR    | __main__:run_tests:306 - Test 1 Failed (Default)
2025-04-10 21:54:31 | ERROR    | __main__:generate:283 - All configured providers failed to generate a response: ['cloud_tier1', 'ollama', 'cloud_tier2']
2025-04-10 21:54:31 | ERROR    | __main__:run_tests:313 - Test 2 Failed (Jeff Override - maybe override not configured or provider failed?)
2025-04-10 21:54:31 | ERROR    | __main__:generate:283 - All configured providers failed to generate a response: ['ollama', 'cloud_tier1', 'cloud_tier2']
2025-04-10 21:54:31 | ERROR    | __main__:run_tests:320 - Test 3 Failed (Ziggy Default)
2025-04-10 21:55:43 | ERROR    | __main__:_generate_openai_compatible:212 - OpenAI API status error for 'cloud_tier1' model llama3-70b-8192: Status=401, Response=<Response [401 Unauthorized]>
2025-04-10 21:55:44 | ERROR    | __main__:_generate_openai_compatible:212 - OpenAI API status error for 'cloud_tier2' model deepseek-chat: Status=401, Response=<Response [401 Unauthorized]>
2025-04-10 21:55:44 | ERROR    | __main__:generate:283 - All configured providers failed to generate a response: ['ollama', 'cloud_tier1', 'cloud_tier2']
2025-04-10 21:55:44 | ERROR    | __main__:run_tests:306 - Test 1 Failed (Default)
2025-04-10 21:55:44 | ERROR    | __main__:_generate_openai_compatible:212 - OpenAI API status error for 'cloud_tier1' model llama3-70b-8192: Status=401, Response=<Response [401 Unauthorized]>
2025-04-10 21:55:45 | ERROR    | __main__:_generate_openai_compatible:212 - OpenAI API status error for 'cloud_tier2' model deepseek-chat: Status=401, Response=<Response [401 Unauthorized]>
2025-04-10 21:55:45 | ERROR    | __main__:generate:283 - All configured providers failed to generate a response: ['cloud_tier1', 'ollama', 'cloud_tier2']
2025-04-10 21:55:45 | ERROR    | __main__:run_tests:313 - Test 2 Failed (Jeff Override - maybe override not configured or provider failed?)
2025-04-10 21:55:45 | ERROR    | __main__:_generate_openai_compatible:212 - OpenAI API status error for 'cloud_tier1' model llama3-70b-8192: Status=401, Response=<Response [401 Unauthorized]>
2025-04-10 21:55:45 | ERROR    | __main__:_generate_openai_compatible:212 - OpenAI API status error for 'cloud_tier2' model deepseek-chat: Status=401, Response=<Response [401 Unauthorized]>
2025-04-10 21:55:45 | ERROR    | __main__:generate:283 - All configured providers failed to generate a response: ['ollama', 'cloud_tier1', 'cloud_tier2']
2025-04-10 21:55:45 | ERROR    | __main__:run_tests:320 - Test 3 Failed (Ziggy Default)
2025-04-10 23:06:09 | ERROR    | __main__:_generate_openai_compatible:190 - OpenAI compatible client 'openrouter_cloud' not initialized or found.
2025-04-10 23:06:09 | ERROR    | __main__:generate:284 - All configured providers failed to generate a response: ['openrouter_cloud', 'ollama']
2025-04-10 23:06:09 | ERROR    | __main__:run_tests:307 - Test 1 Failed (Default)
2025-04-10 23:06:09 | ERROR    | __main__:_generate_openai_compatible:190 - OpenAI compatible client 'openrouter_cloud' not initialized or found.
2025-04-10 23:06:09 | ERROR    | __main__:generate:284 - All configured providers failed to generate a response: ['openrouter_cloud', 'ollama']
2025-04-10 23:06:09 | ERROR    | __main__:run_tests:314 - Test 2 Failed (Jeff Override - maybe override not configured or provider failed?)
2025-04-10 23:06:09 | ERROR    | __main__:_generate_openai_compatible:190 - OpenAI compatible client 'openrouter_cloud' not initialized or found.
2025-04-10 23:06:09 | ERROR    | __main__:generate:284 - All configured providers failed to generate a response: ['openrouter_cloud', 'ollama']
2025-04-10 23:06:09 | ERROR    | __main__:run_tests:321 - Test 3 Failed (Ziggy Default)
2025-04-10 23:10:03 | ERROR    | __main__:_generate_openai_compatible:190 - OpenAI compatible client 'openrouter_cloud' not initialized or found.
2025-04-10 23:10:03 | ERROR    | __main__:generate:284 - All configured providers failed to generate a response: ['openrouter_cloud', 'ollama']
2025-04-10 23:10:03 | ERROR    | __main__:run_tests:307 - Test 1 Failed (Default)
2025-04-10 23:10:03 | ERROR    | __main__:_generate_openai_compatible:190 - OpenAI compatible client 'openrouter_cloud' not initialized or found.
2025-04-10 23:10:03 | ERROR    | __main__:generate:284 - All configured providers failed to generate a response: ['openrouter_cloud', 'ollama']
2025-04-10 23:10:03 | ERROR    | __main__:run_tests:314 - Test 2 Failed (Jeff Override - maybe override not configured or provider failed?)
2025-04-10 23:10:03 | ERROR    | __main__:_generate_openai_compatible:190 - OpenAI compatible client 'openrouter_cloud' not initialized or found.
2025-04-10 23:10:03 | ERROR    | __main__:generate:284 - All configured providers failed to generate a response: ['openrouter_cloud', 'ollama']
2025-04-10 23:10:03 | ERROR    | __main__:run_tests:321 - Test 3 Failed (Ziggy Default)
2025-04-10 23:13:24 | ERROR    | __main__:_generate_openai_compatible:213 - OpenAI API status error for 'openrouter_cloud' model meta-llama/Llama-3-70b-chat-hf: Status=400, Response=<Response [400 Bad Request]>
2025-04-10 23:13:24 | ERROR    | __main__:generate:284 - All configured providers failed to generate a response: ['openrouter_cloud', 'ollama']
2025-04-10 23:13:24 | ERROR    | __main__:run_tests:307 - Test 1 Failed (Default)
2025-04-10 23:13:24 | ERROR    | __main__:_generate_openai_compatible:213 - OpenAI API status error for 'openrouter_cloud' model meta-llama/Llama-3-70b-chat-hf: Status=400, Response=<Response [400 Bad Request]>
2025-04-10 23:13:24 | ERROR    | __main__:generate:284 - All configured providers failed to generate a response: ['openrouter_cloud', 'ollama']
2025-04-10 23:13:24 | ERROR    | __main__:run_tests:314 - Test 2 Failed (Jeff Override - maybe override not configured or provider failed?)
2025-04-10 23:13:24 | ERROR    | __main__:_generate_openai_compatible:213 - OpenAI API status error for 'openrouter_cloud' model meta-llama/Llama-3-70b-chat-hf: Status=400, Response=<Response [400 Bad Request]>
2025-04-10 23:13:24 | ERROR    | __main__:generate:284 - All configured providers failed to generate a response: ['openrouter_cloud', 'ollama']
2025-04-10 23:13:24 | ERROR    | __main__:run_tests:321 - Test 3 Failed (Ziggy Default)

# --- Content from errors_2025-04-11.log ---
2025-04-11 00:08:56 | ERROR    | __main__:_generate_openai_compatible:213 - OpenAI API status error for 'openrouter_cloud' model meta-llama/Llama-3-70b-chat-hf: Status=400, Response=<Response [400 Bad Request]>
2025-04-11 00:08:56 | ERROR    | __main__:generate:284 - All configured providers failed to generate a response: ['openrouter_cloud', 'ollama']
2025-04-11 00:08:56 | ERROR    | __main__:run_tests:307 - Test 1 Failed (Default)
2025-04-11 00:08:56 | ERROR    | __main__:_generate_openai_compatible:213 - OpenAI API status error for 'openrouter_cloud' model meta-llama/Llama-3-70b-chat-hf: Status=400, Response=<Response [400 Bad Request]>
2025-04-11 00:08:56 | ERROR    | __main__:generate:284 - All configured providers failed to generate a response: ['openrouter_cloud', 'ollama']
2025-04-11 00:08:56 | ERROR    | __main__:run_tests:314 - Test 2 Failed (Jeff Override - maybe override not configured or provider failed?)
2025-04-11 00:08:56 | ERROR    | __main__:_generate_openai_compatible:213 - OpenAI API status error for 'openrouter_cloud' model meta-llama/Llama-3-70b-chat-hf: Status=400, Response=<Response [400 Bad Request]>
2025-04-11 00:08:56 | ERROR    | __main__:generate:284 - All configured providers failed to generate a response: ['openrouter_cloud', 'ollama']
2025-04-11 00:08:56 | ERROR    | __main__:run_tests:321 - Test 3 Failed (Ziggy Default)
2025-04-11 00:35:24 | ERROR    | __main__:_generate_openai_compatible:190 - OpenAI compatible client 'openrouter_cloud' not initialized or found.
2025-04-11 00:35:24 | ERROR    | __main__:generate:284 - All configured providers failed to generate a response: ['openrouter_cloud', 'ollama']
2025-04-11 00:35:24 | ERROR    | __main__:run_tests:307 - Test 1 Failed (Default)
2025-04-11 00:35:24 | ERROR    | __main__:_generate_openai_compatible:190 - OpenAI compatible client 'openrouter_cloud' not initialized or found.
2025-04-11 00:35:24 | ERROR    | __main__:generate:284 - All configured providers failed to generate a response: ['openrouter_cloud', 'ollama']
2025-04-11 00:35:24 | ERROR    | __main__:run_tests:314 - Test 2 Failed (Jeff Override - maybe override not configured or provider failed?)
2025-04-11 00:35:24 | ERROR    | __main__:_generate_openai_compatible:190 - OpenAI compatible client 'openrouter_cloud' not initialized or found.
2025-04-11 00:35:24 | ERROR    | __main__:generate:284 - All configured providers failed to generate a response: ['openrouter_cloud', 'ollama']
2025-04-11 00:35:24 | ERROR    | __main__:run_tests:321 - Test 3 Failed (Ziggy Default)
2025-04-11 02:39:23 | ERROR    | NexusAgent:step:99 - Error during LLM generation in Nexus step: LLM.generate() got an unexpected keyword argument 'config'
Traceback (most recent call last):
  File "<frozen runpy>", line 198, in _run_module_as_main
  File "<frozen runpy>", line 88, in _run_code
  File "C:\DreamerAI\engine\ai\nexus.py", line 165, in <module>
    asyncio.run(main())
  File "C:\Users\thecr\AppData\Local\Programs\Python\Python313\Lib\asyncio\runners.py", line 195, in run
    return runner.run(main)
  File "C:\Users\thecr\AppData\Local\Programs\Python\Python313\Lib\asyncio\runners.py", line 118, in run
    return self._loop.run_until_complete(task)
  File "C:\Users\thecr\AppData\Local\Programs\Python\Python313\Lib\asyncio\base_events.py", line 706, in run_until_complete
    self.run_forever()
  File "C:\Users\thecr\AppData\Local\Programs\Python\Python313\Lib\asyncio\base_events.py", line 677, in run_forever
    self._run_once()
  File "C:\Users\thecr\AppData\Local\Programs\Python\Python313\Lib\asyncio\base_events.py", line 2034, in _run_once
    handle._run()
  File "C:\Users\thecr\AppData\Local\Programs\Python\Python313\Lib\asyncio\events.py", line 89, in _run
    self._context.run(self._callback, *self._args)
  File "C:\DreamerAI\engine\ai\nexus.py", line 154, in main
    result = await nexus_agent.run(test_prompt)
  File "C:\DreamerAI\engine\ai\nexus.py", line 119, in run
    result = await self.step(input_data)
> File "C:\DreamerAI\engine\ai\nexus.py", line 94, in step
    response = await self.llm.generate(prompt, config=generation_config)
TypeError: LLM.generate() got an unexpected keyword argument 'config'
2025-04-11 04:37:04 | ERROR    | __main__:_initialize_rag:97 - Failed to initialize ChromaDB or load embedding model: Collection [jeff_context] does not exists
Traceback (most recent call last):
  File "C:\DreamerAI\engine\agents\main_chat.py", line 89, in _initialize_rag
    self.rag_collection = self.rag_client.get_collection(name=collection_name)
  File "C:\DreamerAI\venv\Lib\site-packages\chromadb\api\client.py", line 178, in get_collection
    model = self._server.get_collection(
  File "C:\DreamerAI\venv\Lib\site-packages\chromadb\api\rust.py", line 246, in get_collection
    collection = self.bindings.get_collection(name, tenant, database)
chromadb.errors.NotFoundError: Collection [jeff_context] does not exists
2025-04-11 04:41:47 | ERROR    | __main__:step:176 - LLM generation failed for Jeff: 'ChefJeff' object has no attribute 'llm'
Traceback (most recent call last):
  File "C:\DreamerAI\engine\agents\main_chat.py", line 162, in step
    logger.info(f"Calling LLM (provider for 'Jeff': {self.llm.get_provider_for_agent('Jeff')})")
  File "C:\DreamerAI\venv\Lib\site-packages\pydantic\main.py", line 994, in __getattr__
    raise AttributeError(f'{type(self).__name__!r} object has no attribute {item!r}')
AttributeError: 'ChefJeff' object has no attribute 'llm'

# --- Content from errors_2025-04-12.log ---
2025-04-12 00:05:30 | ERROR    | __main__:run_dreamer_flow:65 - Failed to initialize agents: engine.agents.base.BaseAgent.__init__() got multiple values for keyword argument 'user_dir'
Traceback (most recent call last):
  File "C:\DreamerAI\main.py", line 111, in <module>
    asyncio.run(run_dreamer_flow())
  File "C:\Users\thecr\AppData\Local\Programs\Python\Python313\Lib\asyncio\runners.py", line 195, in run
    return runner.run(main)
  File "C:\Users\thecr\AppData\Local\Programs\Python\Python313\Lib\asyncio\runners.py", line 118, in run
    return self._loop.run_until_complete(task)
  File "C:\Users\thecr\AppData\Local\Programs\Python\Python313\Lib\asyncio\base_events.py", line 706, in run_until_complete
    self.run_forever()
  File "C:\Users\thecr\AppData\Local\Programs\Python\Python313\Lib\asyncio\base_events.py", line 677, in run_forever
    self._run_once()
  File "C:\Users\thecr\AppData\Local\Programs\Python\Python313\Lib\asyncio\base_events.py", line 2034, in _run_once
    handle._run()
  File "C:\Users\thecr\AppData\Local\Programs\Python\Python313\Lib\asyncio\events.py", line 89, in _run
    self._context.run(self._callback, *self._args)
> File "C:\DreamerAI\main.py", line 53, in run_dreamer_flow
    agents["Jeff"] = ChefJeff(llm_instance=llm_service, user_dir=DEFAULT_USER_DIR)
  File "C:\DreamerAI\engine\agents\main_chat.py", line 61, in __init__
    super().__init__(name="Jeff", user_dir=data.get("user_dir"), distill=False, llm=llm_instance, **data)
TypeError: engine.agents.base.BaseAgent.__init__() got multiple values for keyword argument 'user_dir'

Traceback (most recent call last):
  File "C:\DreamerAI\main.py", line 111, in <module>
    asyncio.run(run_dreamer_flow())
  File "C:\Users\thecr\AppData\Local\Programs\Python\Python313\Lib\asyncio\runners.py", line 195, in run
    return runner.run(main)
  File "C:\Users\thecr\AppData\Local\Programs\Python\Python313\Lib\asyncio\runners.py", line 118, in run
    return self._loop.run_until_complete(task)
  File "C:\Users\thecr\AppData\Local\Programs\Python\Python313\Lib\asyncio\base_events.py", line 706, in run_until_complete
    self.run_forever()
  File "C:\Users\thecr\AppData\Local\Programs\Python\Python313\Lib\asyncio\base_events.py", line 677, in run_forever
    self._run_once()
  File "C:\Users\thecr\AppData\Local\Programs\Python\Python313\Lib\asyncio\base_events.py", line 2034, in _run_once
    handle._run()
  File "C:\Users\thecr\AppData\Local\Programs\Python\Python313\Lib\asyncio\events.py", line 89, in _run
    self._context.run(self._callback, *self._args)
  File "C:\DreamerAI\main.py", line 53, in run_dreamer_flow
    agents["Jeff"] = ChefJeff(llm_instance=llm_service, user_dir=DEFAULT_USER_DIR)
  File "C:\DreamerAI\engine\agents\main_chat.py", line 61, in __init__
    super().__init__(name="Jeff", user_dir=data.get("user_dir"), distill=False, llm=llm_instance, **data)
TypeError: engine.agents.base.BaseAgent.__init__() got multiple values for keyword argument 'user_dir'

2025-04-12 00:06:01 | ERROR    | engine.core.workflow:execute:112 - An unexpected error occurred during DreamerFlow execution: ChefJeff.run() got an unexpected keyword argument 'initial_user_input'. Did you mean 'initial_input'?
Traceback (most recent call last):
  File "C:\DreamerAI\main.py", line 111, in <module>
    asyncio.run(run_dreamer_flow())
  File "C:\Users\thecr\AppData\Local\Programs\Python\Python313\Lib\asyncio\runners.py", line 195, in run
    return runner.run(main)
  File "C:\Users\thecr\AppData\Local\Programs\Python\Python313\Lib\asyncio\runners.py", line 118, in run
    return self._loop.run_until_complete(task)
  File "C:\Users\thecr\AppData\Local\Programs\Python\Python313\Lib\asyncio\base_events.py", line 706, in run_until_complete
    self.run_forever()
  File "C:\Users\thecr\AppData\Local\Programs\Python\Python313\Lib\asyncio\base_events.py", line 677, in run_forever
    self._run_once()
  File "C:\Users\thecr\AppData\Local\Programs\Python\Python313\Lib\asyncio\base_events.py", line 2034, in _run_once
    handle._run()
  File "C:\Users\thecr\AppData\Local\Programs\Python\Python313\Lib\asyncio\events.py", line 89, in _run
    self._context.run(self._callback, *self._args)
  File "C:\DreamerAI\main.py", line 90, in run_dreamer_flow
    result = await dreamer_flow.execute(initial_user_input=test_input)
> File "C:\DreamerAI\engine\core\workflow.py", line 86, in execute
    jeff_response = await jeff_agent.run(initial_user_input=initial_user_input) # Changed from guide's user_input to match local var
TypeError: ChefJeff.run() got an unexpected keyword argument 'initial_user_input'. Did you mean 'initial_input'?

Traceback (most recent call last):
  File "C:\DreamerAI\main.py", line 111, in <module>
    asyncio.run(run_dreamer_flow())
  File "C:\Users\thecr\AppData\Local\Programs\Python\Python313\Lib\asyncio\runners.py", line 195, in run
    return runner.run(main)
  File "C:\Users\thecr\AppData\Local\Programs\Python\Python313\Lib\asyncio\runners.py", line 118, in run
    return self._loop.run_until_complete(task)
  File "C:\Users\thecr\AppData\Local\Programs\Python\Python313\Lib\asyncio\base_events.py", line 706, in run_until_complete
    self.run_forever()
  File "C:\Users\thecr\AppData\Local\Programs\Python\Python313\Lib\asyncio\base_events.py", line 677, in run_forever
    self._run_once()
  File "C:\Users\thecr\AppData\Local\Programs\Python\Python313\Lib\asyncio\base_events.py", line 2034, in _run_once
    handle._run()
  File "C:\Users\thecr\AppData\Local\Programs\Python\Python313\Lib\asyncio\events.py", line 89, in _run
    self._context.run(self._callback, *self._args)
  File "C:\DreamerAI\main.py", line 53, in run_dreamer_flow
    agents["Jeff"] = ChefJeff(llm_instance=llm_service, user_dir=DEFAULT_USER_DIR)
  File "C:\DreamerAI\engine\agents\main_chat.py", line 61, in __init__
    super().__init__(name="Jeff", user_dir=data.get("user_dir"), distill=False, llm=llm_instance, **data)
TypeError: engine.agents.base.BaseAgent.__init__() got multiple values for keyword argument 'user_dir'

2025-04-12 00:06:01 | ERROR    | engine.core.workflow:execute:112 - An unexpected error occurred during DreamerFlow execution: ChefJeff.run() got an unexpected keyword argument 'initial_user_input'. Did you mean 'initial_input'?
Traceback (most recent call last):
  File "C:\DreamerAI\main.py", line 111, in <module>
    asyncio.run(run_dreamer_flow())
  File "C:\Users\thecr\AppData\Local\Programs\Python\Python313\Lib\asyncio\runners.py", line 195, in run
    return runner.run(main)
  File "C:\Users\thecr\AppData\Local\Programs\Python\Python313\Lib\asyncio\runners.py", line 118, in run
    return self._loop.run_until_complete(task)
  File "C:\Users\thecr\AppData\Local\Programs\Python\Python313\Lib\asyncio\base_events.py", line 706, in run_until_complete
    self.run_forever()
  File "C:\Users\thecr\AppData\Local\Programs\Python\Python313\Lib\asyncio\base_events.py", line 677, in run_forever
    self._run_once()
  File "C:\Users\thecr\AppData\Local\Programs\Python\Python313\Lib\asyncio\base_events.py", line 2034, in _run_once
    handle._run()
  File "C:\Users\thecr\AppData\Local\Programs\Python\Python313\Lib\asyncio\events.py", line 89, in _run
    self._context.run(self._callback, *self._args)
  File "C:\DreamerAI\main.py", line 90, in run_dreamer_flow
    result = await dreamer_flow.execute(initial_user_input=test_input)
> File "C:\DreamerAI\engine\core\workflow.py", line 86, in execute
    jeff_response = await jeff_agent.run(initial_user_input=initial_user_input) # Changed from guide's user_input to match local var
TypeError: ChefJeff.run() got an unexpected keyword argument 'initial_user_input'. Did you mean 'initial_input'?

Traceback (most recent call last):
  File "C:\DreamerAI\main.py", line 111, in <module>
    asyncio.run(run_dreamer_flow())
  File "C:\Users\thecr\AppData\Local\Programs\Python\Python313\Lib\asyncio\runners.py", line 195, in run
    return runner.run(main)
  File "C:\Users\thecr\AppData\Local\Programs\Python\Python313\Lib\asyncio\runners.py", line 118, in run
    return self._loop.run_until_complete(task)
  File "C:\Users\thecr\AppData\Local\Programs\Python\Python313\Lib\asyncio\base_events.py", line 706, in run_until_complete
    self.run_forever()
  File "C:\Users\thecr\AppData\Local\Programs\Python\Python313\Lib\asyncio\base_events.py", line 677, in run_forever
    self._run_once()
  File "C:\Users\thecr\AppData\Local\Programs\Python\Python313\Lib\asyncio\base_events.py", line 2034, in _run_once
    handle._run()
  File "C:\Users\thecr\AppData\Local\Programs\Python\Python313\Lib\asyncio\events.py", line 89, in _run
    self._context.run(self._callback, *self._args)
  File "C:\DreamerAI\main.py", line 53, in run_dreamer_flow
    agents["Jeff"] = ChefJeff(llm_instance=llm_service, user_dir=DEFAULT_USER_DIR)
  File "C:\DreamerAI\engine\agents\main_chat.py", line 61, in __init__
    super().__init__(name="Jeff", user_dir=data.get("user_dir"), distill=False, llm=llm_instance, **data)
TypeError: engine.agents.base.BaseAgent.__init__() got multiple values for keyword argument 'user_dir'

2025-04-12 00:06:01 | ERROR    | engine.core.workflow:execute:112 - An unexpected error occurred during DreamerFlow execution: ChefJeff.run() got an unexpected keyword argument 'initial_user_input'. Did you mean 'initial_input'?
Traceback (most recent call last):
  File "C:\DreamerAI\main.py", line 111, in <module>
    asyncio.run(run_dreamer_flow())
  File "C:\Users\thecr\AppData\Local\Programs\Python\Python313\Lib\asyncio\runners.py", line 195, in run
    return runner.run(main)
  File "C:\Users\thecr\AppData\Local\Programs\Python\Python313\Lib\asyncio\runners.py", line 118, in run
    return self._loop.run_until_complete(task)
  File "C:\Users\thecr\AppData\Local\Programs\Python\Python313\Lib\asyncio\base_events.py", line 706, in run_until_complete
    self.run_forever()
  File "C:\Users\thecr\AppData\Local\Programs\Python\Python313\Lib\asyncio\base_events.py", line 677, in run_forever
    self._run_once()
  File "C:\Users\thecr\AppData\Local\Programs\Python\Python313\Lib\asyncio\base_events.py", line 2034, in _run_once
    handle._run()
  File "C:\Users\thecr\AppData\Local\Programs\Python\Python313\Lib\asyncio\events.py", line 89, in _run
    self._context.run(self._callback, *self._args)
  File "C:\DreamerAI\main.py", line 90, in run_dreamer_flow
    result = await dreamer_flow.execute(initial_user_input=test_input)
> File "C:\DreamerAI\engine\core\workflow.py", line 86, in execute
    jeff_response = await jeff_agent.run(initial_user_input=initial_user_input) # Changed from guide's user_input to match local var
TypeError: ChefJeff.run() got an unexpected keyword argument 'initial_user_input'. Did you mean 'initial_input'?

Traceback (most recent call last):
  File "C:\DreamerAI\main.py", line 111, in <module>
    asyncio.run(run_dreamer_flow())
  File "C:\Users\thecr\AppData\Local\Programs\Python\Python313\Lib\asyncio\runners.py", line 195, in run
    return runner.run(main)
  File "C:\Users\thecr\AppData\Local\Programs\Python\Python313\Lib\asyncio\runners.py", line 118, in run
    return self._loop.run_until_complete(task)
  File "C:\Users\thecr\AppData\Local\Programs\Python\Python313\Lib\asyncio\base_events.py", line 706, in run_until_complete
    self.run_forever()
  File "C:\Users\thecr\AppData\Local\Programs\Python\Python313\Lib\asyncio\base_events.py", line 677, in run_forever
    self._run_once()
  File "C:\Users\thecr\AppData\Local\Programs\Python\Python313\Lib\asyncio\base_events.py", line 2034, in _run_once
    handle._run()
  File "C:\Users\thecr\AppData\Local\Programs\Python\Python313\Lib\asyncio\events.py", line 89, in _run
    self._context.run(self._callback, *self._args)
  File "C:\DreamerAI\main.py", line 53, in run_dreamer_flow
    agents["Jeff"] = ChefJeff(llm_instance=llm_service, user_dir=DEFAULT_USER_DIR)
  File "C:\DreamerAI\engine\agents\main_chat.py", line 61, in __init__
    super().__init__(name="Jeff", user_dir=data.get("user_dir"), distill=False, llm=llm_instance, **data)
TypeError: engine.agents.base.BaseAgent.__init__() got multiple values for keyword argument 'user_dir'

2025-04-12 00:06:01 | ERROR    | engine.core.workflow:execute:112 - An unexpected error occurred during DreamerFlow execution: ChefJeff.run() got an unexpected keyword argument 'initial_user_input'. Did you mean 'initial_input'?
Traceback (most recent call last):
  File "C:\DreamerAI\main.py", line 111, in <module>
    asyncio.run(run_dreamer_flow())
  File "C:\Users\thecr\AppData\Local\Programs\Python\Python313\Lib\asyncio\runners.py", line 195, in run
    return runner.run(main)
  File "C:\Users\thecr\AppData\Local\Programs\Python\Python313\Lib\asyncio\runners.py", line 118, in run
    return self._loop.run_until_complete(task)
  File "C:\Users\thecr\AppData\Local\Programs\Python\Python313\Lib\asyncio\base_events.py", line 706, in run_until_complete
    self.run_forever()
  File "C:\Users\thecr\AppData\Local\Programs\Python\Python313\Lib\asyncio\base_events.py", line 677, in run_forever
    self._run_once()
  File "C:\Users\thecr\AppData\Local\Programs\Python\Python313\Lib\asyncio\base_events.py", line 2034, in _run_once
    handle._run()
  File "C:\Users\thecr\AppData\Local\Programs\Python\Python313\Lib\asyncio\events.py", line 89, in _run
    self._context.run(self._callback, *self._args)
  File "C:\DreamerAI\main.py", line 90, in run_dreamer_flow
    result = await dreamer_flow.execute(initial_user_input=test_input)
> File "C:\DreamerAI\engine\core\workflow.py", line 86, in execute
    jeff_response = await jeff_agent.run(initial_user_input=initial_user_input) # Changed from guide's user_input to match local var
TypeError: ChefJeff.run() got an unexpected keyword argument 'initial_user_input'. Did you mean 'initial_input'?

Traceback (most recent call last):
  File "C:\DreamerAI\main.py", line 111, in <module>
    asyncio.run(run_dreamer_flow())
  File "C:\Users\thecr\AppData\Local\Programs\Python\Python313\Lib\asyncio\runners.py", line 195, in run
    return runner.run(main)
  File "C:\Users\thecr\AppData\Local\Programs\Python\Python313\Lib\asyncio\runners.py", line 118, in run
    return self._loop.run_until_complete(task)
  File "C:\Users\thecr\AppData\Local\Programs\Python\Python313\Lib\asyncio\base_events.py", line 706, in run_until_complete
    self.run_forever()
  File "C:\Users\thecr\AppData\Local\Programs\Python\Python313\Lib\asyncio\base_events.py", line 677, in run_forever
    self._run_once()
  File "C:\Users\thecr\AppData\Local\Programs\Python\Python313\Lib\asyncio\base_events.py", line 2034, in _run_once
    handle._run()
  File "C:\Users\thecr\AppData\Local\Programs\Python\Python313\Lib\asyncio\events.py", line 89, in _run
    self._context.run(self._callback, *self._args)
  File "C:\DreamerAI\main.py", line 53, in run_dreamer_flow
    agents["Jeff"] = ChefJeff(llm_instance=llm_service, user_dir=DEFAULT_USER_DIR)
  File "C:\DreamerAI\engine\agents\main_chat.py", line 61, in __init__
    super().__init__(name="Jeff", user_dir=data.get("user_dir"), distill=False, llm=llm_instance, **data)
TypeError: engine.agents.base.BaseAgent.__init__() got multiple values for keyword argument 'user_dir'

2025-04-12 00:06:01 | ERROR    | engine.core.workflow:execute:112 - An unexpected error occurred during DreamerFlow execution: ChefJeff.run() got an unexpected keyword argument 'initial_user_input'. Did you mean 'initial_input'?
Traceback (most recent call last):
  File "C:\DreamerAI\main.py", line 111, in <module>
    asyncio.run(run_dreamer_flow())
  File "C:\Users\thecr\AppData\Local\Programs\Python\Python313\Lib\asyncio\runners.py", line 195, in run
    return runner.run(main)
  File "C:\Users\thecr\AppData\Local\Programs\Python\Python313\Lib\asyncio\runners.py", line 118, in run
    return self._loop.run_until_complete(task)
  File "C:\Users\thecr\AppData\Local\Programs\Python\Python313\Lib\asyncio\base_events.py", line 706, in run_until_complete
    self.run_forever()
  File "C:\Users\thecr\AppData\Local\Programs\Python\Python313\Lib\asyncio\base_events.py", line 677, in run_forever
    self._run_once()
  File "C:\Users\thecr\AppData\Local\Programs\Python\Python313\Lib\asyncio\base_events.py", line 2034, in _run_once
    handle._run()
  File "C:\Users\thecr\AppData\Local\Programs\Python\Python313\Lib\asyncio\events.py", line 89, in _run
    self._context.run(self._callback, *self._args)
  File "C:\DreamerAI\main.py", line 90, in run_dreamer_flow
    result = await dreamer_flow.execute(initial_user_input=test_input)
> File "C:\DreamerAI\engine\core\workflow.py", line 86, in execute
    jeff_response = await jeff_agent.run(initial_user_input=initial_user_input) # Changed from guide's user_input to match local var
TypeError: ChefJeff.run() got an unexpected keyword argument 'initial_user_input'. Did you mean 'initial_input'?

Traceback (most recent call last):
  File "C:\DreamerAI\main.py", line 111, in <module>
    asyncio.run(run_dreamer_flow())
  File "C:\Users\thecr\AppData\Local\Programs\Python\Python313\Lib\asyncio\runners.py", line 195, in run
    return runner.run(main)
  File "C:\Users\thecr\AppData\Local\Programs\Python\Python313\Lib\asyncio\runners.py", line 118, in run
    return self._loop.run_until_complete(task)
  File "C:\Users\thecr\AppData\Local\Programs\Python\Python313\Lib\asyncio\base_events.py", line 706, in run_until_complete
    self.run_forever()
  File "C:\Users\thecr\AppData\Local\Programs\Python\Python313\Lib\asyncio\base_events.py", line 677, in run_forever
    self._run_once()
  File "C:\Users\thecr\AppData\Local\Programs\Python\Python313\Lib\asyncio\base_events.py", line 2034, in _run_once
    handle._run()
  File "C:\Users\thecr\AppData\Local\Programs\Python\Python313\Lib\asyncio\events.py", line 89, in _run
    self._context.run(self._callback, *self._args)
  File "C:\DreamerAI\main.py", line 53, in run_dreamer_flow
    agents["Jeff"] = ChefJeff(llm_instance=llm_service, user_dir=DEFAULT_USER_DIR)
  File "C:\DreamerAI\engine\agents\main_chat.py", line 61, in __init__
    super().__init__(name="Jeff", user_dir=data.get("user_dir"), distill=False, llm=llm_instance, **data)
TypeError: engine.agents.base.BaseAgent.__init__() got multiple values for keyword argument 'user_dir'

2025-04-12 00:06:01 | ERROR    | engine.core.workflow:execute:112 - An unexpected error occurred during DreamerFlow execution: ChefJeff.run() got an unexpected keyword argument 'initial_user_input'. Did you mean 'initial_input'?
Traceback (most recent call last):
  File "C:\DreamerAI\main.py", line 111, in <module>
    asyncio.run(run_dreamer_flow())
  File "C:\Users\thecr\AppData\Local\Programs\Python\Python313\Lib\asyncio\runners.py", line 195, in run
    return runner.run(main)
  File "C:\Users\thecr\AppData\Local\Programs\Python\Python313\Lib\asyncio\runners.py", line 118, in run
    return self._loop.run_until_complete(task)
  File "C:\Users\thecr\AppData\Local\Programs\Python\Python313\Lib\asyncio\base_events.py", line 706, in run_until_complete
    self.run_forever()
  File "C:\Users\thecr\AppData\Local\Programs\Python\Python313\Lib\asyncio\base_events.py", line 677, in run_forever
    self._run_once()
  File "C:\Users\thecr\AppData\Local\Programs\Python\Python313\Lib\asyncio\base_events.py", line 2034, in _run_once
    handle._run()
  File "C:\Users\thecr\AppData\Local\Programs\Python\Python313\Lib\asyncio\events.py", line 89, in _run
    self._context.run(self._callback, *self._args)
  File "C:\DreamerAI\main.py", line 90, in run_dreamer_flow
    result = await dreamer_flow.execute(initial_user_input=test_input)
> File "C:\DreamerAI\engine\core\workflow.py", line 86, in execute
    jeff_response = await jeff_agent.run(initial_user_input=initial_user_input) # Changed from guide's user_input to match local var
TypeError: ChefJeff.run() got an unexpected keyword argument 'initial_user_input'. Did you mean 'initial_input'?

Traceback (most recent call last):
  File "C:\DreamerAI\main.py", line 111, in <module>
    asyncio.run(run_dreamer_flow())
  File "C:\Users\thecr\AppData\Local\Programs\Python\Python313\Lib\asyncio\runners.py", line 195, in run
    return runner.run(main)
  File "C:\Users\thecr\AppData\Local\Programs\Python\Python313\Lib\asyncio\runners.py", line 118, in run
    return self._loop.run_until_complete(task)
  File "C:\Users\thecr\AppData\Local\Programs\Python\Python313\Lib\asyncio\base_events.py", line 706, in run_until_complete
    self.run_forever()
  File "C:\Users\thecr\AppData\Local\Programs\Python\Python313\Lib\asyncio\base_events.py", line 677, in run_forever
    self._run_once()
  File "C:\Users\thecr\AppData\Local\Programs\Python\Python313\Lib\asyncio\base_events.py", line 2034, in _run_once
    handle._run()
  File "C:\Users\thecr\AppData\Local\Programs\Python\Python313\Lib\asyncio\events.py", line 89, in _run
    self._context.run(self._callback, *self._args)
  File "C:\DreamerAI\main.py", line 53, in run_dreamer_flow
    agents["Jeff"] = ChefJeff(llm_instance=llm_service, user_dir=DEFAULT_USER_DIR)
  File "C:\DreamerAI\engine\agents\main_chat.py", line 61, in __init__
    super().__init__(name="Jeff", user_dir=data.get("user_dir"), distill=False, llm=llm_instance, **data)
TypeError: engine.agents.base.BaseAgent.__init__() got multiple values for keyword argument 'user_dir'

2025-04-12 00:06:01 | ERROR    | engine.core.workflow:execute:112 - An unexpected error occurred during DreamerFlow execution: ChefJeff.run() got an unexpected keyword argument 'initial_user_input'. Did you mean 'initial_input'?
Traceback (most recent call last):
  File "C:\DreamerAI\main.py", line 111, in <module>
    asyncio.run(run_dreamer_flow())
  File "C:\Users\thecr\AppData\Local\Programs\Python\Python313\Lib\asyncio\runners.py", line 195, in run
    return runner.run(main)
  File "C:\Users\thecr\AppData\Local\Programs\Python\Python313\Lib\asyncio\runners.py", line 118, in run
    return self._loop.run_until_complete(task)
  File "C:\Users\thecr\AppData\Local\Programs\Python\Python313\Lib\asyncio\base_events.py", line 706, in run_until_complete
    self.run_forever()
  File "C:\Users\thecr\AppData\Local\Programs\Python\Python313\Lib\asyncio\base_events.py", line 677, in run_forever
    self._run_once()
  File "C:\Users\thecr\AppData\Local\Programs\Python\Python313\Lib\asyncio\base_events.py", line 2034, in _run_once
    handle._run()
  File "C:\Users\thecr\AppData\Local\Programs\Python\Python313\Lib\asyncio\events.py", line 89, in _run
    self._context.run(self._callback, *self._args)
  File "C:\DreamerAI\main.py", line 90, in run_dreamer_flow
    result = await dreamer_flow.execute(initial_user_input=test_input)
> File "C:\DreamerAI\engine\core\workflow.py", line 86, in execute
    jeff_response = await jeff_agent.run(initial_user_input=initial_user_input) # Changed from guide's user_input to match local var
TypeError: ChefJeff.run() got an unexpected keyword argument 'initial_user_input'. Did you mean 'initial_input'?

Traceback (most recent call last):
  File "C:\DreamerAI\main.py", line 111, in <module>
    asyncio.run(run_dreamer_flow())
  File "C:\Users\thecr\AppData\Local\Programs\Python\Python313\Lib\asyncio\runners.py", line 195, in run
    return runner.run(main)
  File "C:\Users\thecr\AppData\Local\Programs\Python\Python313\Lib\asyncio\runners.py", line 118, in run
    return self._loop.run_until_complete(task)
  File "C:\Users\thecr\AppData\Local\Programs\Python\Python313\Lib\asyncio\base_events.py", line 706, in run_until_complete
    self.run_forever()
  File "C:\Users\thecr\AppData\Local\Programs\Python\Python313\Lib\asyncio\base_events.py", line 677, in run_forever
    self._run_once()
  File "C:\Users\thecr\AppData\Local\Programs\Python\Python313\Lib\asyncio\base_events.py", line 2034, in _run_once
    handle._run()
  File "C:\Users\thecr\AppData\Local\Programs\Python\Python313\Lib\asyncio\events.py", line 89, in _run
    self._context.run(self._callback, *self._args)
  File "C:\DreamerAI\main.py", line 53, in run_dreamer_flow
    agents["Jeff"] = ChefJeff(llm_instance=llm_service, user_dir=DEFAULT_USER_DIR)
  File "C:\DreamerAI\engine\agents\main_chat.py", line 61, in __init__
    super().__init__(name="Jeff", user_dir=data.get("user_dir"), distill=False, llm=llm_instance, **data)
TypeError: engine.agents.base.BaseAgent.__init__() got multiple values for keyword argument 'user_dir'

2025-04-12 00:06:01 | ERROR    | engine.core.workflow:execute:112 - An unexpected error occurred during DreamerFlow execution: ChefJeff.run() got an unexpected keyword argument 'initial_user_input'. Did you mean 'initial_input'?
Traceback (most recent call last):
  File "C:\DreamerAI\main.py", line 111, in <module>
    asyncio.run(run_dreamer_flow())
  File "C:\Users\thecr\AppData\Local\Programs\Python\Python313\Lib\asyncio\runners.py", line 195, in run
    return runner.run(main)
  File "C:\Users\thecr\AppData\Local\Programs\Python\Python313\Lib\asyncio\runners.py", line 118, in run
    return self._loop.run_until_complete(task)
  File "C:\Users\thecr\AppData\Local\Programs\Python\Python313\Lib\asyncio\base_events.py", line 706, in run_until_complete
    self.run_forever()
  File "C:\Users\thecr\AppData\Local\Programs\Python\Python313\Lib\asyncio\base_events.py", line 677, in run_forever
    self._run_once()
  File "C:\Users\thecr\AppData\Local\Programs\Python\Python313\Lib\asyncio\base_events.py", line 2034, in _run_once
    handle._run()
  File "C:\Users\thecr\AppData\Local\Programs\Python\Python313\Lib\asyncio\events.py", line 89, in _run
    self._context.run(self._callback, *self._args)
  File "C:\DreamerAI\main.py", line 90, in run_dreamer_flow
    result = await dreamer_flow.execute(initial_user_input=test_input)
> File "C:\DreamerAI\engine\core\workflow.py", line 86, in execute
    jeff_response = await jeff_agent.run(initial_user_input=initial_user_input) # Changed from guide's user_input to match local var
TypeError: ChefJeff.run() got an unexpected keyword argument 'initial_user_input'. Did you mean 'initial_input'?

Traceback (most recent call last):
  File "C:\DreamerAI\main.py", line 111, in <module>
    asyncio.run(run_dreamer_flow())
  File "C:\Users\thecr\AppData\Local\Programs\Python\Python313\Lib\asyncio\runners.py", line 195, in run
    return runner.run(main)
  File "C:\Users\thecr\AppData\Local\Programs\Python\Python313\Lib\asyncio\runners.py", line 118, in run
    return self._loop.run_until_complete(task)
  File "C:\Users\thecr\AppData\Local\Programs\Python\Python313\Lib\asyncio\base_events.py", line 706, in run_until_complete
    self.run_forever()
  File "C:\Users\thecr\AppData\Local\Programs\Python\Python313\Lib\asyncio\base_events.py", line 677, in run_forever
    self._run_once()
  File "C:\Users\thecr\AppData\Local\Programs\Python\Python313\Lib\asyncio\base_events.py", line 2034, in _run_once
    handle._run()
  File "C:\Users\thecr\AppData\Local\Programs\Python\Python313\Lib\asyncio\events.py", line 89, in _run
    self._context.run(self._callback, *self._args)
  File "C:\DreamerAI\main.py", line 53, in run_dreamer_flow
    agents["Jeff"] = ChefJeff(llm_instance=llm_service, user_dir=DEFAULT_USER_DIR)
  File "C:\DreamerAI\engine\agents\main_chat.py", line 61, in __init__
    super().__init__(name="Jeff", user_dir=data.get("user_dir"), distill=False, llm=llm_instance, **data)
TypeError: engine.agents.base.BaseAgent.__init__() got multiple values for keyword argument 'user_dir'

2025-04-12 00:06:01 | ERROR    | engine.core.workflow:execute:112 - An unexpected error occurred during DreamerFlow execution: ChefJeff.run() got an unexpected keyword argument 'initial_user_input'. Did you mean 'initial_input'?
Traceback (most recent call last):
  File "C:\DreamerAI\main.py", line 111, in <module>
    asyncio.run(run_dreamer_flow())
  File "C:\Users\thecr\AppData\Local\Programs\Python\Python313\Lib\asyncio\runners.py", line 195, in run
    return runner.run(main)
  File "C:\Users\thecr\AppData\Local\Programs\Python\Python313\Lib\asyncio\runners.py", line 118, in run
    return self._loop.run_until_complete(task)
  File "C:\Users\thecr\AppData\Local\Programs\Python\Python313\Lib\asyncio\base_events.py", line 706, in run_until_complete
    self.run_forever()
  File "C:\Users\thecr\AppData\Local\Programs\Python\Python313\Lib\asyncio\base_events.py", line 677, in run_forever
    self._run_once()
  File "C:\Users\thecr\AppData\Local\Programs\Python\Python313\Lib\asyncio\base_events.py", line 2034, in _run_once
    handle._run()
  File "C:\Users\thecr\AppData\Local\Programs\Python\Python313\Lib\asyncio\events.py", line 89, in _run
    self._context.run(self._callback, *self._args)
  File "C:\DreamerAI\main.py", line 90, in run_dreamer_flow
    result = await dreamer_flow.execute(initial_user_input=test_input)
> File "C:\DreamerAI\engine\core\workflow.py", line 86, in execute
    jeff_response = await jeff_agent.run(initial_user_input=initial_user_input) # Changed from guide's user_input to match local var
TypeError: ChefJeff.run() got an unexpected keyword argument 'initial_user_input'. Did you mean 'initial_input'?

Traceback (most recent call last):
  File "C:\DreamerAI\main.py", line 111, in <module>
    asyncio.run(run_dreamer_flow())
  File "C:\Users\thecr\AppData\Local\Programs\Python\Python313\Lib\asyncio\runners.py", line 195, in run
    return runner.run(main)
  File "C:\Users\thecr\AppData\Local\Programs\Python\Python313\Lib\asyncio\runners.py", line 118, in run
    return self._loop.run_until_complete(task)
  File "C:\Users\thecr\AppData\Local\Programs\Python\Python313\Lib\asyncio\base_events.py", line 706, in run_until_complete
    self.run_forever()
  File "C:\Users\thecr\AppData\Local\Programs\Python\Python313\Lib\asyncio\base_events.py", line 677, in run_forever
    self._run_once()
  File "C:\Users\thecr\AppData\Local\Programs\Python\Python313\Lib\asyncio\base_events.py", line 2034, in _run_once
    handle._run()
  File "C:\Users\thecr\AppData\Local\Programs\Python\Python313\Lib\asyncio\events.py", line 89, in _run
    self._context.run(self._callback, *self._args)
  File "C:\DreamerAI\main.py", line 53, in run_dreamer_flow
    agents["Jeff"] = ChefJeff(llm_instance=llm_service, user_dir=DEFAULT_USER_DIR)
  File "C:\DreamerAI\engine\agents\main_chat.py", line 61, in __init__
    super().__init__(name="Jeff", user_dir=data.get("user_dir"), distill=False, llm=llm_instance, **data)
TypeError: engine.agents.base.BaseAgent.__init__() got multiple values for keyword argument 'user_dir'

2025-04-12 00:06:01 | ERROR    | engine.core.workflow:execute:112 - An unexpected error occurred during DreamerFlow execution: ChefJeff.run() got an unexpected keyword argument 'initial_user_input'. Did you mean 'initial_input'?
Traceback (most recent call last):
  File "C:\DreamerAI\main.py", line 111, in <module>
    asyncio.run(run_dreamer_flow())
  File "C:\Users\thecr\AppData\Local\Programs\Python\Python313\Lib\asyncio\runners.py", line 195, in run
    return runner.run(main)
  File "C:\Users\thecr\AppData\Local\Programs\Python\Python313\Lib\asyncio\runners.py", line 118, in run
    return self._loop.run_until_complete(task)
  File "C:\Users\thecr\AppData\Local\Programs\Python\Python313\Lib\asyncio\base_events.py", line 706, in run_until_complete
    self.run_forever()
  File "C:\Users\thecr\AppData\Local\Programs\Python\Python313\Lib\asyncio\base_events.py", line 677, in run_forever
    self._run_once()
  File "C:\Users\thecr\AppData\Local\Programs\Python\Python313\Lib\asyncio\base_events.py", line 2034, in _run_once
    handle._run()
  File "C:\Users\thecr\AppData\Local\Programs\Python\Python313\Lib\asyncio\events.py", line 89, in _run
    self._context.run(self._callback, *self._args)
  File "C:\DreamerAI\main.py", line 90, in run_dreamer_flow
    result = await dreamer_flow.execute(initial_user_input=test_input)
> File "C:\DreamerAI\engine\core\workflow.py", line 86, in execute
    jeff_response = await jeff_agent.run(initial_user_input=initial_user_input) # Changed from guide's user_input to match local var
TypeError: ChefJeff.run() got an unexpected keyword argument 'initial_user_input'. Did you mean 'initial_input'?

Traceback (most recent call last):
  File "C:\DreamerAI\main.py", line 111, in <module>
    asyncio.run(run_dreamer_flow())
  File "C:\Users\thecr\AppData\Local\Programs\Python\Python313\Lib\asyncio\runners.py", line 195, in run
    return runner.run(main)
  File "C:\Users\thecr\AppData\Local\Programs\Python\Python313\Lib\asyncio\runners.py", line 118, in run
    return self._loop.run_until_complete(task)
  File "C:\Users\thecr\AppData\Local\Programs\Python\Python313\Lib\asyncio\base_events.py", line 706, in run_until_complete
    self.run_forever()
  File "C:\Users\thecr\AppData\Local\Programs\Python\Python313\Lib\asyncio\base_events.py", line 677, in run_forever
    self._run_once()
  File "C:\Users\thecr\AppData\Local\Programs\Python\Python313\Lib\asyncio\base_events.py", line 2034, in _run_once
    handle._run()
  File "C:\Users\thecr\AppData\Local\Programs\Python\Python313\Lib\asyncio\events.py", line 89, in _run
    self._context.run(self._callback, *self._args)
  File "C:\DreamerAI\main.py", line 53, in run_dreamer_flow
    agents["Jeff"] = ChefJeff(llm_instance=llm_service, user_dir=DEFAULT_USER_DIR)
  File "C:\DreamerAI\engine\agents\main_chat.py", line 61, in __init__
    super().__init__(name="Jeff", user_dir=data.get("user_dir"), distill=False, llm=llm_instance, **data)
TypeError: engine.agents.base.BaseAgent.__init__() got multiple values for keyword argument 'user_dir'

2025-04-12 00:06:01 | ERROR    | engine.core.workflow:execute:112 - An unexpected error occurred during DreamerFlow execution: ChefJeff.run() got an unexpected keyword argument 'initial_user_input'. Did you mean 'initial_input'?
Traceback (most recent call last):
  File "C:\DreamerAI\main.py", line 111, in <module>
    asyncio.run(run_dreamer_flow())
  File "C:\Users\thecr\AppData\Local\Programs\Python\Python313\Lib\asyncio\runners.py", line 195, in run
    return runner.run(main)
  File "C:\Users\thecr\AppData\Local\Programs\Python\Python313\Lib\asyncio\runners.py", line 118, in run
    return self._loop.run_until_complete(task)
  File "C:\Users\thecr\AppData\Local\Programs\Python\Python313\Lib\asyncio\base_events.py", line 706, in run_until_complete
    self.run_forever()
  File "C:\Users\thecr\AppData\Local\Programs\Python\Python313\Lib\asyncio\base_events.py", line 677, in run_forever
    self._run_once()
  File "C:\Users\thecr\AppData\Local\Programs\Python\Python313\Lib\asyncio\base_events.py", line 2034, in _run_once
    handle._run()
  File "C:\Users\thecr\AppData\Local\Programs\Python\Python313\Lib\asyncio\events.py", line 89, in _run
    self._context.run(self._callback, *self._args)
  File "C:\DreamerAI\main.py", line 90, in run_dreamer_flow
    result = await dreamer_flow.execute(initial_user_input=test_input)
> File "C:\DreamerAI\engine\core\workflow.py", line 86, in execute
    jeff_response = await jeff_agent.run(initial_user_input=initial_user_input) # Changed from guide's user_input to match local var
TypeError: ChefJeff.run() got an unexpected keyword argument 'initial_user_input'. Did you mean 'initial_input'?

Traceback (most recent call last):
  File "C:\DreamerAI\main.py", line 111, in <module>
    asyncio.run(run_dreamer_flow())
  File "C:\Users\thecr\AppData\Local\Programs\Python\Python313\Lib\asyncio\runners.py", line 195, in run
    return runner.run(main)
  File "C:\Users\thecr\AppData\Local\Programs\Python\Python313\Lib\asyncio\runners.py", line 118, in run
    return self._loop.run_until_complete(task)
  File "C:\Users\thecr\AppData\Local\Programs\Python\Python313\Lib\asyncio\base_events.py", line 706, in run_until_complete
    self.run_forever()
  File "C:\Users\thecr\AppData\Local\Programs\Python\Python313\Lib\asyncio\base_events.py", line 677, in run_forever
    self._run_once()
  File "C:\Users\thecr\AppData\Local\Programs\Python\Python313\Lib\asyncio\base_events.py", line 2034, in _run_once
    handle._run()
  File "C:\Users\thecr\AppData\Local\Programs\Python\Python313\Lib\asyncio\events.py", line 89, in _run
    self._context.run(self._callback, *self._args)
  File "C:\DreamerAI\main.py", line 53, in run_dreamer_flow
    agents["Jeff"] = ChefJeff(llm_instance=llm_service, user_dir=DEFAULT_USER_DIR)
  File "C:\DreamerAI\engine\agents\main_chat.py", line 61, in __init__
    super().__init__(name="Jeff", user_dir=data.get("user_dir"), distill=False, llm=llm_instance, **data)
TypeError: engine.agents.base.BaseAgent.__init__() got multiple values for keyword argument 'user_dir'

2025-04-12 00:06:01 | ERROR    | engine.core.workflow:execute:112 - An unexpected error occurred during DreamerFlow execution: ChefJeff.run() got an unexpected keyword argument 'initial_user_input'. Did you mean 'initial_input'?
Traceback (most recent call last):
  File "C:\DreamerAI\main.py", line 111, in <module>
    asyncio.run(run_dreamer_flow())
  File "C:\Users\thecr\AppData\Local\Programs\Python\Python313\Lib\asyncio\runners.py", line 195, in run
    return runner.run(main)
  File "C:\Users\thecr\AppData\Local\Programs\Python\Python313\Lib\asyncio\runners.py", line 118, in run
    return self._loop.run_until_complete(task)
  File "C:\Users\thecr\AppData\Local\Programs\Python\Python313\Lib\asyncio\base_events.py", line 706, in run_until_complete
    self.run_forever()
  File "C:\Users\thecr\AppData\Local\Programs\Python\Python313\Lib\asyncio\base_events.py", line 677, in run_forever
    self._run_once()
  File "C:\Users\thecr\AppData\Local\Programs\Python\Python313\Lib\asyncio\base_events.py", line 2034, in _run_once
    handle._run()
  File "C:\Users\thecr\AppData\Local\Programs\Python\Python313\Lib\asyncio\events.py", line 89, in _run
    self._context.run(self._callback, *self._args)
  File "C:\DreamerAI\main.py", line 90, in run_dreamer_flow
    result = await dreamer_flow.execute(initial_user_input=test_input)
> File "C:\DreamerAI\engine\core\workflow.py", line 86, in execute
    jeff_response = await jeff_agent.run(initial_user_input=initial_user_input) # Changed from guide's user_input to match local var
TypeError: ChefJeff.run() got an unexpected keyword argument 'initial_user_input'. Did you mean 'initial_input'?

Traceback (most recent call last):
  File "C:\DreamerAI\main.py", line 111, in <module>
    asyncio.run(run_dreamer_flow())
  File "C:\Users\thecr\AppData\Local\Programs\Python\Python313\Lib\asyncio\runners.py", line 195, in run
    return runner.run(main)
  File "C:\Users\thecr\AppData\Local\Programs\Python\Python313\Lib\asyncio\runners.py", line 118, in run
    return self._loop.run_until_complete(task)
  File "C:\Users\thecr\AppData\Local\Programs\Python\Python313\Lib\asyncio\base_events.py", line 706, in run_until_complete
    self.run_forever()
  File "C:\Users\thecr\AppData\Local\Programs\Python\Python313\Lib\asyncio\base_events.py", line 677, in run_forever
    self._run_once()
  File "C:\Users\thecr\AppData\Local\Programs\Python\Python313\Lib\asyncio\base_events.py", line 2034, in _run_once
    handle._run()
  File "C:\Users\thecr\AppData\Local\Programs\Python\Python313\Lib\asyncio\events.py", line 89, in _run
    self._context.run(self._callback, *self._args)
  File "C:\DreamerAI\main.py", line 53, in run_dreamer_flow
    agents["Jeff"] = ChefJeff(llm_instance=llm_service, user_dir=DEFAULT_USER_DIR)
  File "C:\DreamerAI\engine\agents\main_chat.py", line 61, in __init__
    super().__init__(name="Jeff", user_dir=data.get("user_dir"), distill=False, llm=llm_instance, **data)
TypeError: engine.agents.base.BaseAgent.__init__() got multiple values for keyword argument 'user_dir'

2025-04-12 00:06:01 | ERROR    | engine.core.workflow:execute:112 - An unexpected error occurred during DreamerFlow execution: ChefJeff.run() got an unexpected keyword argument 'initial_user_input'. Did you mean 'initial_input'?
Traceback (most recent call last):
  File "C:\DreamerAI\main.py", line 111, in <module>
    asyncio.run(run_dreamer_flow())
  File "C:\Users\thecr\AppData\Local\Programs\Python\Python313\Lib\asyncio\runners.py", line 195, in run
    return runner.run(main)
  File "C:\Users\thecr\AppData\Local\Programs\Python\Python313\Lib\asyncio\runners.py", line 118, in run
    return self._loop.run_until_complete(task)
  File "C:\Users\thecr\AppData\Local\Programs\Python\Python313\Lib\asyncio\base_events.py", line 706, in run_until_complete
    self.run_forever()
  File "C:\Users\thecr\AppData\Local\Programs\Python\Python313\Lib\asyncio\base_events.py", line 677, in run_forever
    self._run_once()
  File "C:\Users\thecr\AppData\Local\Programs\Python\Python313\Lib\asyncio\base_events.py", line 2034, in _run_once
    handle._run()
  File "C:\Users\thecr\AppData\Local\Programs\Python\Python313\Lib\asyncio\events.py", line 89, in _run
    self._context.run(self._callback, *self._args)
  File "C:\DreamerAI\main.py", line 90, in run_dreamer_flow
    result = await dreamer_flow.execute(initial_user_input=test_input)
> File "C:\DreamerAI\engine\core\workflow.py", line 86, in execute
    jeff_response = await jeff_agent.run(initial_user_input=initial_user_input) # Changed from guide's user_input to match local var
TypeError: ChefJeff.run() got an unexpected keyword argument 'initial_user_input'. Did you mean 'initial_input'?

Traceback (most recent call last):
  File "C:\DreamerAI\main.py", line 111, in <module>
    asyncio.run(run_dreamer_flow())
  File "C:\Users\thecr\AppData\Local\Programs\Python\Python313\Lib\asyncio\runners.py", line 195, in run
    return runner.run(main)
  File "C:\Users\thecr\AppData\Local\Programs\Python\Python313\Lib\asyncio\runners.py", line 118, in run
    return self._loop.run_until_complete(task)
  File "C:\Users\thecr\AppData\Local\Programs\Python\Python313\Lib\asyncio\base_events.py", line 706, in run_until_complete
    self.run_forever()
  File "C:\Users\thecr\AppData\Local\Programs\Python\Python313\Lib\asyncio\base_events.py", line 677, in run_forever
    self._run_once()
  File "C:\Users\thecr\AppData\Local\Programs\Python\Python313\Lib\asyncio\base_events.py", line 2034, in _run_once
    handle._run()
  File "C:\Users\thecr\AppData\Local\Programs\Python\Python313\Lib\asyncio\events.py", line 89, in _run
    self._context.run(self._callback, *self._args)
  File "C:\DreamerAI\main.py", line 53, in run_dreamer_flow
    agents["Jeff"] = ChefJeff(llm_instance=llm_service, user_dir=DEFAULT_USER_DIR)
  File "C:\DreamerAI\engine\agents\main_chat.py", line 61, in __init__
    super().__init__(name="Jeff", user_dir=data.get("user_dir"), distill=False, llm=llm_instance, **data)
TypeError: engine.agents.base.BaseAgent.__init__() got multiple values for keyword argument 'user_dir'

2025-04-12 00:06:01 | ERROR    | engine.core.workflow:execute:112 - An unexpected error occurred during DreamerFlow execution: ChefJeff.run() got an unexpected keyword argument 'initial_user_input'. Did you mean 'initial_input'?
Traceback (most recent call last):
  File "C:\DreamerAI\main.py", line 111, in <module>
    asyncio.run(run_dreamer_flow())
  File "C:\Users\thecr\AppData\Local\Programs\Python\Python313\Lib\asyncio\runners.py", line 195, in run
    return runner.run(main)
  File "C:\Users\thecr\AppData\Local\Programs\Python\Python313\Lib\asyncio\runners.py", line 118, in run
    return self._loop.run_until_complete(task)
  File "C:\Users\thecr\AppData\Local\Programs\Python\Python313\Lib\asyncio\base_events.py", line 706, in run_until_complete
    self.run_forever()
  File "C:\Users\thecr\AppData\Local\Programs\Python\Python313\Lib\asyncio\base_events.py", line 677, in run_forever
    self._run_once()
  File "C:\Users\thecr\AppData\Local\Programs\Python\Python313\Lib\asyncio\base_events.py", line 2034, in _run_once
    handle._run()
  File "C:\Users\thecr\AppData\Local\Programs\Python\Python313\Lib\asyncio\events.py", line 89, in _run
    self._context.run(self._callback, *self._args)
  File "C:\DreamerAI\main.py", line 90, in run_dreamer_flow
    result = await dreamer_flow.execute(initial_user_input=test_input)
> File "C:\DreamerAI\engine\core\workflow.py", line 86, in execute
    jeff_response = await jeff_agent.run(initial_user_input=initial_user_input) # Changed from guide's user_input to match local var
TypeError: ChefJeff.run() got an unexpected keyword argument 'initial_user_input'. Did you mean 'initial_input'?

Traceback (most recent call last):
  File "C:\DreamerAI\main.py", line 111, in <module>
    asyncio.run(run_dreamer_flow())
  File "C:\Users\thecr\AppData\Local\Programs\Python\Python313\Lib\asyncio\runners.py", line 195, in run
    return runner.run(main)
  File "C:\Users\thecr\AppData\Local\Programs\Python\Python313\Lib\asyncio\runners.py", line 118, in run
    return self._loop.run_until_complete(task)
  File "C:\Users\thecr\AppData\Local\Programs\Python\Python313\Lib\asyncio\base_events.py", line 706, in run_until_complete
    self.run_forever()
  File "C:\Users\thecr\AppData\Local\Programs\Python\Python313\Lib\asyncio\base_events.py", line 677, in run_forever
    self._run_once()
  File "C:\Users\thecr\AppData\Local\Programs\Python\Python313\Lib\asyncio\base_events.py", line 2034, in _run_once
    handle._run()
  File "C:\Users\thecr\AppData\Local\Programs\Python\Python313\Lib\asyncio\events.py", line 89, in _run
    self._context.run(self._callback, *self._args)
  File "C:\DreamerAI\main.py", line 53, in run_dreamer_flow
    agents["Jeff"] = ChefJeff(llm_instance=llm_service, user_dir=DEFAULT_USER_DIR)
  File "C:\DreamerAI\engine\agents\main_chat.py", line 61, in __init__
    super().__init__(name="Jeff", user_dir=data.get("user_dir"), distill=False, llm=llm_instance, **data)
TypeError: engine.agents.base.BaseAgent.__init__() got multiple values for keyword argument 'user_dir'

2025-04-12 00:06:01 | ERROR    | engine.core.workflow:execute:112 - An unexpected error occurred during DreamerFlow execution: ChefJeff.run() got an unexpected keyword argument 'initial_user_input'. Did you mean 'initial_input'?
Traceback (most recent call last):
  File "C:\DreamerAI\main.py", line 111, in <module>
    asyncio.run(run_dreamer_flow())
  File "C:\Users\thecr\AppData\Local\Programs\Python\Python313\Lib\asyncio\runners.py", line 195, in run
    return runner.run(main)
  File "C:\Users\thecr\AppData\Local\Programs\Python\Python313\Lib\asyncio\runners.py", line 118, in run
    return self._loop.run_until_complete(task)
  File "C:\Users\thecr\AppData\Local\Programs\Python\Python313\Lib\asyncio\base_events.py", line 706, in run_until_complete
    self.run_forever()
  File "C:\Users\thecr\AppData\Local\Programs\Python\Python313\Lib\asyncio\base_events.py", line 677, in run_forever
    self._run_once()
  File "C:\Users\thecr\AppData\Local\Programs\Python\Python313\Lib\asyncio\base_events.py", line 2034, in _run_once
    handle._run()
  File "C:\Users\thecr\AppData\Local\Programs\Python\Python313\Lib\asyncio\events.py", line 89, in _run
    self._context.run(self._callback, *self._args)
  File "C:\DreamerAI\main.py", line 90, in run_dreamer_flow
    result = await dreamer_flow.execute(initial_user_input=test_input)
> File "C:\DreamerAI\engine\core\workflow.py", line 86, in execute
    jeff_response = await jeff_agent.run(initial_user_input=initial_user_input) # Changed from guide's user_input to match local var
TypeError: ChefJeff.run() got an unexpected keyword argument 'initial_user_input'. Did you mean 'initial_input'?

Traceback (most recent call last):
  File "C:\DreamerAI\main.py", line 111, in <module>
    asyncio.run(run_dreamer_flow())
  File "C:\Users\thecr\AppData\Local\Programs\Python\Python313\Lib\asyncio\runners.py", line 195, in run
    return runner.run(main)
  File "C:\Users\thecr\AppData\Local\Programs\Python\Python313\Lib\asyncio\runners.py", line 118, in run
    return self._loop.run_until_complete(task)
  File "C:\Users\thecr\AppData\Local\Programs\Python\Python313\Lib\asyncio\base_events.py", line 706, in run_until_complete
    self.run_forever()
  File "C:\Users\thecr\AppData\Local\Programs\Python\Python313\Lib\asyncio\base_events.py", line 677, in run_forever
    self._run_once()
  File "C:\Users\thecr\AppData\Local\Programs\Python\Python313\Lib\asyncio\base_events.py", line 2034, in _run_once
    handle._run()
  File "C:\Users\thecr\AppData\Local\Programs\Python\Python313\Lib\asyncio\events.py", line 89, in _run
    self._context.run(self._callback, *self._args)
  File "C:\DreamerAI\main.py", line 53, in run_dreamer_flow
    agents["Jeff"] = ChefJeff(llm_instance=llm_service, user_dir=DEFAULT_USER_DIR)
  File "C:\DreamerAI\engine\agents\main_chat.py", line 61, in __init__
    super().__init__(name="Jeff", user_dir=data.get("user_dir"), distill=False, llm=llm_instance, **data)
TypeError: engine.agents.base.BaseAgent.__init__() got multiple values for keyword argument 'user_dir'

2025-04-12 00:06:01 | ERROR    | engine.core.workflow:execute:112 - An unexpected error occurred during DreamerFlow execution: ChefJeff.run() got an unexpected keyword argument 'initial_user_input'. Did you mean 'initial_input'?
Traceback (most recent call last):
  File "C:\DreamerAI\main.py", line 111, in <module>
    asyncio.run(run_dreamer_flow())
  File "C:\Users\thecr\AppData\Local\Programs\Python\Python313\Lib\asyncio\runners.py", line 195, in run
    return runner.run(main)
  File "C:\Users\thecr\AppData\Local\Programs\Python\Python313\Lib\asyncio\runners.py", line 118, in run
    return self._loop.run_until_complete(task)
  File "C:\Users\thecr\AppData\Local\Programs\Python\Python313\Lib\asyncio\base_events.py", line 706, in run_until_complete
    self.run_forever()
  File "C:\Users\thecr\AppData\Local\Programs\Python\Python313\Lib\asyncio\base_events.py", line 677, in run_forever
    self._run_once()
  File "C:\Users\thecr\AppData\Local\Programs\Python\Python313\Lib\asyncio\base_events.py", line 2034, in _run_once
    handle._run()
  File "C:\Users\thecr\AppData\Local\Programs\Python\Python313\Lib\asyncio\events.py", line 89, in _run
    self._context.run(self._callback, *self._args)
  File "C:\DreamerAI\main.py", line 90, in run_dreamer_flow
    result = await dreamer_flow.execute(initial_user_input=test_input)
> File "C:\DreamerAI\engine\core\workflow.py", line 86, in execute
    jeff_response = await jeff_agent.run(initial_user_input=initial_user_input) # Changed from guide's user_input to match local var
TypeError: ChefJeff.run() got an unexpected keyword argument 'initial_user_input'. Did you mean 'initial_input'?

Traceback (most recent call last):
  File "C:\DreamerAI\main.py", line 111, in <module>
    asyncio.run(run_dreamer_flow())
  File "C:\Users\thecr\AppData\Local\Programs\Python\Python313\Lib\asyncio\runners.py", line 195, in run
    return runner.run(main)
  File "C:\Users\thecr\AppData\Local\Programs\Python\Python313\Lib\asyncio\runners.py", line 118, in run
    return self._loop.run_until_complete(task)
  File "C:\Users\thecr\AppData\Local\Programs\Python\Python313\Lib\asyncio\base_events.py", line 706, in run_until_complete
    self.run_forever()
  File "C:\Users\thecr\AppData\Local\Programs\Python\Python313\Lib\asyncio\base_events.py", line 677, in run_forever
    self._run_once()
  File "C:\Users\thecr\AppData\Local\Programs\Python\Python313\Lib\asyncio\base_events.py", line 2034, in _run_once
    handle._run()
  File "C:\Users\thecr\AppData\Local\Programs\Python\Python313\Lib\asyncio\events.py", line 89, in _run
    self._context.run(self._callback, *self._args)
  File "C:\DreamerAI\main.py", line 53, in run_dreamer_flow
    agents["Jeff"] = ChefJeff(llm_instance=llm_service, user_dir=DEFAULT_USER_DIR)
  File "C:\DreamerAI\engine\agents\main_chat.py", line 61, in __init__
    super().__init__(name="Jeff", user_dir=data.get("user_dir"), distill=False, llm=llm_instance, **data)
TypeError: engine.agents.base.BaseAgent.__init__() got multiple values for keyword argument 'user_dir'

2025-04-12 00:06:01 | ERROR    | engine.core.workflow:execute:112 - An unexpected error occurred during DreamerFlow execution: ChefJeff.run() got an unexpected keyword argument 'initial_user_input'. Did you mean 'initial_input'?
Traceback (most recent call last):
  File "C:\DreamerAI\main.py", line 111, in <module>
    asyncio.run(run_dreamer_flow())
  File "C:\Users\thecr\AppData\Local\Programs\Python\Python313\Lib\asyncio\runners.py", line 195, in run
    return runner.run(main)
  File "C:\Users\thecr\AppData\Local\Programs\Python\Python313\Lib\asyncio\runners.py", line 118, in run
    return self._loop.run_until_complete(task)
  File "C:\Users\thecr\AppData\Local\Programs\Python\Python313\Lib\asyncio\base_events.py", line 706, in run_until_complete
    self.run_forever()
  File "C:\Users\thecr\AppData\Local\Programs\Python\Python313\Lib\asyncio\base_events.py", line 677, in run_forever
    self._run_once()
  File "C:\Users\thecr\AppData\Local\Programs\Python\Python313\Lib\asyncio\base_events.py", line 2034, in _run_once
    handle._run()
  File "C:\Users\thecr\AppData\Local\Programs\Python\Python313\Lib\asyncio\events.py", line 89, in _run
    self._context.run(self._callback, *self._args)
  File "C:\DreamerAI\main.py", line 90, in run_dreamer_flow
    result = await dreamer_flow.execute(initial_user_input=test_input)
> File "C:\DreamerAI\engine\core\workflow.py", line 86, in execute
    jeff_response = await jeff_agent.run(initial_user_input=initial_user_input) # Changed from guide's user_input to match local var
TypeError: ChefJeff.run() got an unexpected keyword argument 'initial_user_input'. Did you mean 'initial_input'?

Traceback (most recent call last):
  File "C:\DreamerAI\main.py", line 111, in <module>
    asyncio.run(run_dreamer_flow())
  File "C:\Users\thecr\AppData\Local\Programs\Python\Python313\Lib\asyncio\runners.py", line 195, in run
    return runner.run(main)
  File "C:\Users\thecr\AppData\Local\Programs\Python\Python313\Lib\asyncio\runners.py", line 118, in run
    return self._loop.run_until_complete(task)
  File "C:\Users\thecr\AppData\Local\Programs\Python\Python313\Lib\asyncio\base_events.py", line 706, in run_until_complete
    self.run_forever()
  File "C:\Users\thecr\AppData\Local\Programs\Python\Python313\Lib\asyncio\base_events.py", line 677, in run_forever
    self._run_once()
  File "C:\Users\thecr\AppData\Local\Programs\Python\Python313\Lib\asyncio\base_events.py", line 2034, in _run_once
    handle._run()
  File "C:\Users\thecr\AppData\Local\Programs\Python\Python313\Lib\asyncio\events.py", line 89, in _run
    self._context.run(self._callback, *self._args)
  File "C:\DreamerAI\main.py", line 53, in run_dreamer_flow
    agents["Jeff"] = ChefJeff(llm_instance=llm_service, user_dir=DEFAULT_USER_DIR)
  File "C:\DreamerAI\engine\agents\main_chat.py", line 61, in __init__
    super().__init__(name="Jeff", user_dir=data.get("user_dir"), distill=False, llm=llm_instance, **data)
TypeError: engine.agents.base.BaseAgent.__init__() got multiple values for keyword argument 'user_dir'

2025-04-12 00:06:01 | ERROR    | engine.core.workflow:execute:112 - An unexpected error occurred during DreamerFlow execution: ChefJeff.run() got an unexpected keyword argument 'initial_user_input'. Did you mean 'initial_input'?
Traceback (most recent call last):
  File "C:\DreamerAI\main.py", line 111, in <module>
    asyncio.run(run_dreamer_flow())
  File "C:\Users\thecr\AppData\Local\Programs\Python\Python313\Lib\asyncio\runners.py", line 195, in run
    return runner.run(main)
  File "C:\Users\thecr\AppData\Local\Programs\Python\Python313\Lib\asyncio\runners.py", line 118, in run
    return self._loop.run_until_complete(task)
  File "C:\Users\thecr\AppData\Local\Programs\Python\Python313\Lib\asyncio\base_events.py", line 706, in run_until_complete
    self.run_forever()
  File "C:\Users\thecr\AppData\Local\Programs\Python\Python313\Lib\asyncio\base_events.py", line 677, in run_forever
    self._run_once()
  File "C:\Users\thecr\AppData\Local\Programs\Python\Python313\Lib\asyncio\base_events.py", line 2034, in _run_once
    handle._run()
  File "C:\Users\thecr\AppData\Local\Programs\Python\Python313\Lib\asyncio\events.py", line 89, in _run
    self._context.run(self._callback, *self._args)
  File "C:\DreamerAI\main.py", line 90, in run_dreamer_flow
    result = await dreamer_flow.execute(initial_user_input=test_input)
> File "C:\DreamerAI\engine\core\workflow.py", line 86, in execute
    jeff_response = await jeff_agent.run(initial_user_input=initial_user_input) # Changed from guide's user_input to match local var
TypeError: ChefJeff.run() got an unexpected keyword argument 'initial_user_input'. Did you mean 'initial_input'?

Traceback (most recent call last):
  File "C:\DreamerAI\main.py", line 111, in <module>
    asyncio.run(run_dreamer_flow())
  File "C:\Users\thecr\AppData\Local\Programs\Python\Python313\Lib\asyncio\runners.py", line 195, in run
    return runner.run(main)
  File "C:\Users\thecr\AppData\Local\Programs\Python\Python313\Lib\asyncio\runners.py", line 118, in run
    return self._loop.run_until_complete(task)
  File "C:\Users\thecr\AppData\Local\Programs\Python\Python313\Lib\asyncio\base_events.py", line 706, in run_until_complete
    self.run_forever()
  File "C:\Users\thecr\AppData\Local\Programs\Python\Python313\Lib\asyncio\base_events.py", line 677, in run_forever
    self._run_once()
  File "C:\Users\thecr\AppData\Local\Programs\Python\Python313\Lib\asyncio\base_events.py", line 2034, in _run_once
    handle._run()
  File "C:\Users\thecr\AppData\Local\Programs\Python\Python313\Lib\asyncio\events.py", line 89, in _run
    self._context.run(self._callback, *self._args)
  File "C:\DreamerAI\main.py", line 53, in run_dreamer_flow
    agents["Jeff"] = ChefJeff(llm_instance=llm_service, user_dir=DEFAULT_USER_DIR)
  File "C:\DreamerAI\engine\agents\main_chat.py", line 61, in __init__
    super().__init__(name="Jeff", user_dir=data.get("user_dir"), distill=False, llm=llm_instance, **data)
TypeError: engine.agents.base.BaseAgent.__init__() got multiple values for keyword argument 'user_dir'

2025-04-12 00:06:01 | ERROR    | engine.core.workflow:execute:112 - An unexpected error occurred during DreamerFlow execution: ChefJeff.run() got an unexpected keyword argument 'initial_user_input'. Did you mean 'initial_input'?
Traceback (most recent call last):
  File "C:\DreamerAI\main.py", line 111, in <module>
    asyncio.run(run_dreamer_flow())
  File "C:\Users\thecr\AppData\Local\Programs\Python\Python313\Lib\asyncio\runners.py", line 195, in run
    return runner.run(main)
  File "C:\Users\thecr\AppData\Local\Programs\Python\Python313\Lib\asyncio\runners.py", line 118, in run
    return self._loop.run_until_complete(task)
  File "C:\Users\thecr\AppData\Local\Programs\Python\Python313\Lib\asyncio\base_events.py", line 706, in run_until_complete
    self.run_forever()
  File "C:\Users\thecr\AppData\Local\Programs\Python\Python313\Lib\asyncio\base_events.py", line 677, in run_forever
    self._run_once()
  File "C:\Users\thecr\AppData\Local\Programs\Python\Python313\Lib\asyncio\base_events.py", line 2034, in _run_once
    handle._run()
  File "C:\Users\thecr\AppData\Local\Programs\Python\Python313\Lib\asyncio\events.py", line 89, in _run
    self._context.run(self._callback, *self._args)
  File "C:\DreamerAI\main.py", line 90, in run_dreamer_flow
    result = await dreamer_flow.execute(initial_user_input=test_input)
> File "C:\DreamerAI\engine\core\workflow.py", line 86, in execute
    jeff_response = await jeff_agent.run(initial_user_input=initial_user_input) # Changed from guide's user_input to match local var
TypeError: ChefJeff.run() got an unexpected keyword argument 'initial_user_input'. Did you mean 'initial_input'?

Traceback (most recent call last):
  File "C:\DreamerAI\main.py", line 111, in <module>
    asyncio.run(run_dreamer_flow())
  File "C:\Users\thecr\AppData\Local\Programs\Python\Python313\Lib\asyncio\runners.py", line 195, in run
    return runner.run(main)
  File "C:\Users\thecr\AppData\Local\Programs\Python\Python313\Lib\asyncio\runners.py", line 118, in run
    return self._loop.run_until_complete(task)
  File "C:\Users\thecr\AppData\Local\Programs\Python\Python313\Lib\asyncio\base_events.py", line 706, in run_until_complete
    self.run_forever()
  File "C:\Users\thecr\AppData\Local\Programs\Python\Python313\Lib\asyncio\base_events.py", line 677, in run_forever
    self._run_once()
  File "C:\Users\thecr\AppData\Local\Programs\Python\Python313\Lib\asyncio\base_events.py", line 2034, in _run_once
    handle._run()
  File "C:\Users\thecr\AppData\Local\Programs\Python\Python313\Lib\asyncio\events.py", line 89, in _run
    self._context.run(self._callback, *self._args)
  File "C:\DreamerAI\main.py", line 53, in run_dreamer_flow
    agents["Jeff"] = ChefJeff(llm_instance=llm_service, user_dir=DEFAULT_USER_DIR)
  File "C:\DreamerAI\engine\agents\main_chat.py", line 61, in __init__
    super().__init__(name="Jeff", user_dir=data.get("user_dir"), distill=False, llm=llm_instance, **data)
TypeError: engine.agents.base.BaseAgent.__init__() got multiple values for keyword argument 'user_dir'

2025-04-12 00:06:01 | ERROR    | engine.core.workflow:execute:112 - An unexpected error occurred during DreamerFlow execution: ChefJeff.run() got an unexpected keyword argument 'initial_user_input'. Did you mean 'initial_input'?
Traceback (most recent call last):
  File "C:\DreamerAI\main.py", line 111, in <module>
    asyncio.run(run_dreamer_flow())
  File "C:\Users\thecr\AppData\Local\Programs\Python\Python313\Lib\asyncio\runners.py", line 195, in run
    return runner.run(main)
  File "C:\Users\thecr\AppData\Local\Programs\Python\Python313\Lib\asyncio\runners.py", line 118, in run
    return self._loop.run_until_complete(task)
  File "C:\Users\thecr\AppData\Local\Programs\Python\Python313\Lib\asyncio\base_events.py", line 706, in run_until_complete
    self.run_forever()
  File "C:\Users\thecr\AppData\Local\Programs\Python\Python313\Lib\asyncio\base_events.py", line 677, in run_forever
    self._run_once()
  File "C:\Users\thecr\AppData\Local\Programs\Python\Python313\Lib\asyncio\base_events.py", line 2034, in _run_once
    handle._run()
  File "C:\Users\thecr\AppData\Local\Programs\Python\Python313\Lib\asyncio\events.py", line 89, in _run
    self._context.run(self._callback, *self._args)
  File "C:\DreamerAI\main.py", line 90, in run_dreamer_flow
    result = await dreamer_flow.execute(initial_user_input=test_input)
> File "C:\DreamerAI\engine\core\workflow.py", line 86, in execute
    jeff_response = await jeff_agent.run(initial_user_input=initial_user_input) # Changed from guide's user_input to match local var
TypeError: ChefJeff.run() got an unexpected keyword argument 'initial_user_input'. Did you mean 'initial_input'?

Traceback (most recent call last):
  File "C:\DreamerAI\main.py", line 111, in <module>
    asyncio.run(run_dreamer_flow())
  File "C:\Users\thecr\AppData\Local\Programs\Python\Python313\Lib\asyncio\runners.py", line 195, in run
    return runner.run(main)
  File "C:\Users\thecr\AppData\Local\Programs\Python\Python313\Lib\asyncio\runners.py", line 118, in run
    return self._loop.run_until_complete(task)
  File "C:\Users\thecr\AppData\Local\Programs\Python\Python313\Lib\asyncio\base_events.py", line 706, in run_until_complete
    self.run_forever()
  File "C:\Users\thecr\AppData\Local\Programs\Python\Python313\Lib\asyncio\base_events.py", line 677, in run_forever
    self._run_once()
  File "C:\Users\thecr\AppData\Local\Programs\Python\Python313\Lib\asyncio\base_events.py", line 2034, in _run_once
    handle._run()
  File "C:\Users\thecr\AppData\Local\Programs\Python\Python313\Lib\asyncio\events.py", line 89, in _run
    self._context.run(self._callback, *self._args)
  File "C:\DreamerAI\main.py", line 53, in run_dreamer_flow
    agents["Jeff"] = ChefJeff(llm_instance=llm_service, user_dir=DEFAULT_USER_DIR)
  File "C:\DreamerAI\engine\agents\main_chat.py", line 61, in __init__
    super().__init__(name="Jeff", user_dir=data.get("user_dir"), distill=False, llm=llm_instance, **data)
TypeError: engine.agents.base.BaseAgent.__init__() got multiple values for keyword argument 'user_dir'

2025-04-12 00:06:01 | ERROR    | engine.core.workflow:execute:112 - An unexpected error occurred during DreamerFlow execution: ChefJeff.run() got an unexpected keyword argument 'initial_user_input'. Did you mean 'initial_input'?
Traceback (most recent call last):
  File "C:\DreamerAI\main.py", line 111, in <module>
    asyncio.run(run_dreamer_flow())
  File "C:\Users\thecr\AppData\Local\Programs\Python\Python313\Lib\asyncio\runners.py", line 195, in run
    return runner.run(main)
  File "C:\Users\thecr\AppData\Local\Programs\Python\Python313\Lib\asyncio\runners.py", line 118, in run
    return self._loop.run_until_complete(task)
  File "C:\Users\thecr\AppData\Local\Programs\Python\Python313\Lib\asyncio\base_events.py", line 706, in run_until_complete
    self.run_forever()
  File "C:\Users\thecr\AppData\Local\Programs\Python\Python313\Lib\asyncio\base_events.py", line 677, in run_forever
    self._run_once()
  File "C:\Users\thecr\AppData\Local\Programs\Python\Python313\Lib\asyncio\base_events.py", line 2034, in _run_once
    handle._run()
  File "C:\Users\thecr\AppData\Local\Programs\Python\Python313\Lib\asyncio\events.py", line 89, in _run
    self._context.run(self._callback, *self._args)
  File "C:\DreamerAI\main.py", line 90, in run_dreamer_flow
    result = await dreamer_flow.execute(initial_user_input=test_input)
> File "C:\DreamerAI\engine\core\workflow.py", line 86, in execute
    jeff_response = await jeff_agent.run(initial_user_input=initial_user_input) # Changed from guide's user_input to match local var
TypeError: ChefJeff.run() got an unexpected keyword argument 'initial_user_input'. Did you mean 'initial_input'?

Traceback (most recent call last):
  File "C:\DreamerAI\main.py", line 111, in <module>
    asyncio.run(run_dreamer_flow())
  File "C:\Users\thecr\AppData\Local\Programs\Python\Python313\Lib\asyncio\runners.py", line 195, in run
    return runner.run(main)
  File "C:\Users\thecr\AppData\Local\Programs\Python\Python313\Lib\asyncio\runners.py", line 118, in run
    return self._loop.run_until_complete(task)
  File "C:\Users\thecr\AppData\Local\Programs\Python\Python313\Lib\asyncio\base_events.py", line 706, in run_until_complete
    self.run_forever()
  File "C:\Users\thecr\AppData\Local\Programs\Python\Python313\Lib\asyncio\base_events.py", line 677, in run_forever
    self._run_once()
  File "C:\Users\thecr\AppData\Local\Programs\Python\Python313\Lib\asyncio\base_events.py", line 2034, in _run_once
    handle._run()
  File "C:\Users\thecr\AppData\Local\Programs\Python\Python313\Lib\asyncio\events.py", line 89, in _run
    self._context.run(self._callback, *self._args)
  File "C:\DreamerAI\main.py", line 53, in run_dreamer_flow
    agents["Jeff"] = ChefJeff(llm_instance=llm_service, user_dir=DEFAULT_USER_DIR)
  File "C:\DreamerAI\engine\agents\main_chat.py", line 61, in __init__
    super().__init__(name="Jeff", user_dir=data.get("user_dir"), distill=False, llm=llm_instance, **data)
TypeError: engine.agents.base.BaseAgent.__init__() got multiple values for keyword argument 'user_dir'

2025-04-12 00:06:01 | ERROR    | engine.core.workflow:execute:112 - An unexpected error occurred during DreamerFlow execution: ChefJeff.run() got an unexpected keyword argument 'initial_user_input'. Did you mean 'initial_input'?
Traceback (most recent call last):
  File "C:\DreamerAI\main.py", line 111, in <module>
    asyncio.run(run_dreamer_flow())
  File "C:\Users\thecr\AppData\Local\Programs\Python\Python313\Lib\asyncio\runners.py", line 195, in run
    return runner.run(main)
  File "C:\Users\thecr\AppData\Local\Programs\Python\Python313\Lib\asyncio\runners.py", line 118, in run
    return self._loop.run_until_complete(task)
  File "C:\Users\thecr\AppData\Local\Programs\Python\Python313\Lib\asyncio\base_events.py", line 706, in run_until_complete
    self.run_forever()
  File "C:\Users\thecr\AppData\Local\Programs\Python\Python313\Lib\asyncio\base_events.py", line 677, in run_forever
    self._run_once()
  File "C:\Users\thecr\AppData\Local\Programs\Python\Python313\Lib\asyncio\base_events.py", line 2034, in _run_once
    handle._run()
  File "C:\Users\thecr\AppData\Local\Programs\Python\Python313\Lib\asyncio\events.py", line 89, in _run
    self._context.run(self._callback, *self._args)
  File "C:\DreamerAI\main.py", line 90, in run_dreamer_flow
    result = await dreamer_flow.execute(initial_user_input=test_input)
> File "C:\DreamerAI\engine\core\workflow.py", line 86, in execute
    jeff_response = await jeff_agent.run(initial_user_input=initial_user_input) # Changed from guide's user_input to match local var
TypeError: ChefJeff.run() got an unexpected keyword argument 'initial_user_input'. Did you mean 'initial_input'?

Traceback (most recent call last):
  File "C:\DreamerAI\main.py", line 111, in <module>
    asyncio.run(run_dreamer_flow())
  File "C:\Users\thecr\AppData\Local\Programs\Python\Python313\Lib\asyncio\runners.py", line 195, in run
    return runner.run(main)
  File "C:\Users\thecr\AppData\Local\Programs\Python\Python313\Lib\asyncio\runners.py", line 118, in run
    return self._loop.run_until_complete(task)
  File "C:\Users\thecr\AppData\Local\Programs\Python\Python313\Lib\asyncio\base_events.py", line 706, in run_until_complete
    self.run_forever()
  File "C:\Users\thecr\AppData\Local\Programs\Python\Python313\Lib\asyncio\base_events.py", line 677, in run_forever
    self._run_once()
  File "C:\Users\thecr\AppData\Local\Programs\Python\Python313\Lib\asyncio\base_events.py", line 2034, in _run_once
    handle._run()
  File "C:\Users\thecr\AppData\Local\Programs\Python\Python313\Lib\asyncio\events.py", line 89, in _run
    self._context.run(self._callback, *self._args)
  File "C:\DreamerAI\main.py", line 53, in run_dreamer_flow
    agents["Jeff"] = ChefJeff(llm_instance=llm_service, user_dir=DEFAULT_USER_DIR)
  File "C:\DreamerAI\engine\agents\main_chat.py", line 61, in __init__
    super().__init__(name="Jeff", user_dir=data.get("user_dir"), distill=False, llm=llm_instance, **data)
TypeError: engine.agents.base.BaseAgent.__init__() got multiple values for keyword argument 'user_dir'

2025-04-12 00:06:01 | ERROR    | engine.core.workflow:execute:112 - An unexpected error occurred during DreamerFlow execution: ChefJeff.run() got an unexpected keyword argument 'initial_user_input'. Did you mean 'initial_input'?
Traceback (most recent call last):
  File "C:\DreamerAI\main.py", line 111, in <module>
    asyncio.run(run_dreamer_flow())
  File "C:\Users\thecr\AppData\Local\Programs\Python\Python313\Lib\asyncio\runners.py", line 195, in run
    return runner.run(main)
  File "C:\Users\thecr\AppData\Local\Programs\Python\Python313\Lib\asyncio\runners.py", line 118, in run
    return self._loop.run_until_complete(task)
  File "C:\Users\thecr\AppData\Local\Programs\Python\Python313\Lib\asyncio\base_events.py", line 706, in run_until_complete
    self.run_forever()
  File "C:\Users\thecr\AppData\Local\Programs\Python\Python313\Lib\asyncio\base_events.py", line 677, in run_forever
    self._run_once()
  File "C:\Users\thecr\AppData\Local\Programs\Python\Python313\Lib\asyncio\base_events.py", line 2034, in _run_once
    handle._run()
  File "C:\Users\thecr\AppData\Local\Programs\Python\Python313\Lib\asyncio\events.py", line 89, in _run
    self._context.run(self._callback, *self._args)
  File "C:\DreamerAI\main.py", line 90, in run_dreamer_flow
    result = await dreamer_flow.execute(initial_user_input=test_input)
> File "C:\DreamerAI\engine\core\workflow.py", line 86, in execute
    jeff_response = await jeff_agent.run(initial_user_input=initial_user_input) # Changed from guide's user_input to match local var
TypeError: ChefJeff.run() got an unexpected keyword argument 'initial_user_input'. Did you mean 'initial_input'?

Traceback (most recent call last):
  File "C:\DreamerAI\main.py", line 111, in <module>
    asyncio.run(run_dreamer_flow())
  File "C:\Users\thecr\AppData\Local\Programs\Python\Python313\Lib\asyncio\runners.py", line 195, in run
    return runner.run(main)
  File "C:\Users\thecr\AppData\Local\Programs\Python\Python313\Lib\asyncio\runners.py", line 118, in run
    return self._loop.run_until_complete(task)
  File "C:\Users\thecr\AppData\Local\Programs\Python\Python313\Lib\asyncio\base_events.py", line 706, in run_until_complete
    self.run_forever()
  File "C:\Users\thecr\AppData\Local\Programs\Python\Python313\Lib\asyncio\base_events.py", line 677, in run_forever
    self._run_once()
  File "C:\Users\thecr\AppData\Local\Programs\Python\Python313\Lib\asyncio\base_events.py", line 2034, in _run_once
    handle._run()
  File "C:\Users\thecr\AppData\Local\Programs\Python\Python313\Lib\asyncio\events.py", line 89, in _run
    self._context.run(self._callback, *self._args)
  File "C:\DreamerAI\main.py", line 53, in run_dreamer_flow
    agents["Jeff"] = ChefJeff(llm_instance=llm_service, user_dir=DEFAULT_USER_DIR)
  File "C:\DreamerAI\engine\agents\main_chat.py", line 61, in __init__
    super().__init__(name="Jeff", user_dir=data.get("user_dir"), distill=False, llm=llm_instance, **data)
TypeError: engine.agents.base.BaseAgent.__init__() got multiple values for keyword argument 'user_dir'

2025-04-12 00:06:01 | ERROR    | engine.core.workflow:execute:112 - An unexpected error occurred during DreamerFlow execution: ChefJeff.run() got an unexpected keyword argument 'initial_user_input'. Did you mean 'initial_input'?
Traceback (most recent call last):
  File "C:\DreamerAI\main.py", line 111, in <module>
    asyncio.run(run_dreamer_flow())
  File "C:\Users\thecr\AppData\Local\Programs\Python\Python313\Lib\asyncio\runners.py", line 195, in run
    return runner.run(main)
  File "C:\Users\thecr\AppData\Local\Programs\Python\Python313\Lib\asyncio\runners.py", line 118, in run
    return self._loop.run_until_complete(task)
  File "C:\Users\thecr\AppData\Local\Programs\Python\Python313\Lib\asyncio\base_events.py", line 706, in run_until_complete
    self.run_forever()
  File "C:\Users\thecr\AppData\Local\Programs\Python\Python313\Lib\asyncio\base_events.py", line 677, in run_forever
    self._run_once()
  File "C:\Users\thecr\AppData\Local\Programs\Python\Python313\Lib\asyncio\base_events.py", line 2034, in _run_once
    handle._run()
  File "C:\Users\thecr\AppData\Local\Programs\Python\Python313\Lib\asyncio\events.py", line 89, in _run
    self._context.run(self._callback, *self._args)
  File "C:\DreamerAI\main.py", line 90, in run_dreamer_flow
    result = await dreamer_flow.execute(initial_user_input=test_input)
> File "C:\DreamerAI\engine\core\workflow.py", line 86, in execute
    jeff_response = await jeff_agent.run(initial_user_input=initial_user_input) # Changed from guide's user_input to match local var
TypeError: ChefJeff.run() got an unexpected keyword argument 'initial_user_input'. Did you mean 'initial_input'?

Traceback (most recent call last):
  File "C:\DreamerAI\main.py", line 111, in <module>
    asyncio.run(run_dreamer_flow())
  File "C:\Users\thecr\AppData\Local\Programs\Python\Python313\Lib\asyncio\runners.py", line 195, in run
    return runner.run(main)
  File "C:\Users\thecr\AppData\Local\Programs\Python\Python313\Lib\asyncio\runners.py", line 118, in run
    return self._loop.run_until_complete(task)
  File "C:\Users\thecr\AppData\Local\Programs\Python\Python313\Lib\asyncio\base_events.py", line 706, in run_until_complete
    self.run_forever()
  File "C:\Users\thecr\AppData\Local\Programs\Python\Python313\Lib\asyncio\base_events.py", line 677, in run_forever
    self._run_once()
  File "C:\Users\thecr\AppData\Local\Programs\Python\Python313\Lib\asyncio\base_events.py", line 2034, in _run_once
    handle._run()
  File "C:\Users\thecr\AppData\Local\Programs\Python\Python313\Lib\asyncio\events.py", line 89, in _run
    self._context.run(self._callback, *self._args)
  File "C:\DreamerAI\main.py", line 53, in run_dreamer_flow
    agents["Jeff"] = ChefJeff(llm_instance=llm_service, user_dir=DEFAULT_USER_DIR)
  File "C:\DreamerAI\engine\agents\main_chat.py", line 61, in __init__
    super().__init__(name="Jeff", user_dir=data.get("user_dir"), distill=False, llm=llm_instance, **data)
TypeError: engine.agents.base.BaseAgent.__init__() got multiple values for keyword argument 'user_dir'

2025-04-12 00:06:01 | ERROR    | engine.core.workflow:execute:112 - An unexpected error occurred during DreamerFlow execution: ChefJeff.run() got an unexpected keyword argument 'initial_user_input'. Did you mean 'initial_input'?
Traceback (most recent call last):
  File "C:\DreamerAI\main.py", line 111, in <module>
    asyncio.run(run_dreamer_flow())
  File "C:\Users\thecr\AppData\Local\Programs\Python\Python313\Lib\asyncio\runners.py", line 195, in run
    return runner.run(main)
  File "C:\Users\thecr\AppData\Local\Programs\Python\Python313\Lib\asyncio\runners.py", line 118, in run
    return self._loop.run_until_complete(task)
  File "C:\Users\thecr\AppData\Local\Programs\Python\Python313\Lib\asyncio\base_events.py", line 706, in run_until_complete
    self.run_forever()
  File "C:\Users\thecr\AppData\Local\Programs\Python\Python313\Lib\asyncio\base_events.py", line 677, in run_forever
    self._run_once()
  File "C:\Users\thecr\AppData\Local\Programs\Python\Python313\Lib\asyncio\base_events.py", line 2034, in _run_once
    handle._run()
  File "C:\Users\thecr\AppData\Local\Programs\Python\Python313\Lib\asyncio\events.py", line 89, in _run
    self._context.run(self._callback, *self._args)
  File "C:\DreamerAI\main.py", line 90, in run_dreamer_flow
    result = await dreamer_flow.execute(initial_user_input=test_input)
> File "C:\DreamerAI\engine\core\workflow.py", line 86, in execute
    jeff_response = await jeff_agent.run(initial_user_input=initial_user_input) # Changed from guide's user_input to match local var
TypeError: ChefJeff.run() got an unexpected keyword argument 'initial_user_input'. Did you mean 'initial_input'?

Traceback (most recent call last):
  File "C:\DreamerAI\main.py", line 111, in <module>
    asyncio.run(run_dreamer_flow())
  File "C:\Users\thecr\AppData\Local\Programs\Python\Python313\Lib\asyncio\runners.py", line 195, in run
    return runner.run(main)
  File "C:\Users\thecr\AppData\Local\Programs\Python\Python313\Lib\asyncio\runners.py", line 118, in run
    return self._loop.run_until_complete(task)
  File "C:\Users\thecr\AppData\Local\Programs\Python\Python313\Lib\asyncio\base_events.py", line 706, in run_until_complete
    self.run_forever()
  File "C:\Users\thecr\AppData\Local\Programs\Python\Python313\Lib\asyncio\base_events.py", line 677, in run_forever
    self._run_once()
  File "C:\Users\thecr\AppData\Local\Programs\Python\Python313\Lib\asyncio\base_events.py", line 2034, in _run_once
    handle._run()
  File "C:\Users\thecr\AppData\Local\Programs\Python\Python313\Lib\asyncio\events.py", line 89, in _run
    self._context.run(self._callback, *self._args)
  File "C:\DreamerAI\main.py", line 53, in run_dreamer_flow
    agents["Jeff"] = ChefJeff(llm_instance=llm_service, user_dir=DEFAULT_USER_DIR)
  File "C:\DreamerAI\engine\agents\main_chat.py", line 61, in __init__
    super().__init__(name="Jeff", user_dir=data.get("user_dir"), distill=False, llm=llm_instance, **data)
TypeError: engine.agents.base.BaseAgent.__init__() got multiple values for keyword argument 'user_dir'

2025-04-12 00:06:01 | ERROR    | engine.core.workflow:execute:112 - An unexpected error occurred during DreamerFlow execution: ChefJeff.run() got an unexpected keyword argument 'initial_user_input'. Did you mean 'initial_input'?
Traceback (most recent call last):
  File "C:\DreamerAI\main.py", line 111, in <module>
    asyncio.run(run_dreamer_flow())
  File "C:\Users\thecr\AppData\Local\Programs\Python\Python313\Lib\asyncio\runners.py", line 195, in run
    return runner.run(main)
  File "C:\Users\thecr\AppData\Local\Programs\Python\Python313\Lib\asyncio\runners.py", line 118, in run
    return self._loop.run_until_complete(task)
  File "C:\Users\thecr\AppData\Local\Programs\Python\Python313\Lib\asyncio\base_events.py", line 706, in run_until_complete
    self.run_forever()
  File "C:\Users\thecr\AppData\Local\Programs\Python\Python313\Lib\asyncio\base_events.py", line 677, in run_forever
    self._run_once()
  File "C:\Users\thecr\AppData\Local\Programs\Python\Python313\Lib\asyncio\base_events.py", line 2034, in _run_once
    handle._run()
  File "C:\Users\thecr\AppData\Local\Programs\Python\Python313\Lib\asyncio\events.py", line 89, in _run
    self._context.run(self._callback, *self._args)
  File "C:\DreamerAI\main.py", line 90, in run_dreamer_flow
    result = await dreamer_flow.execute(initial_user_input=test_input)
> File "C:\DreamerAI\engine\core\workflow.py", line 86, in execute
    jeff_response = await jeff_agent.run(initial_user_input=initial_user_input) # Changed from guide's user_input to match local var
TypeError: ChefJeff.run() got an unexpected keyword argument 'initial_user_input'. Did you mean 'initial_input'?

Traceback (most recent call last):
  File "C:\DreamerAI\main.py", line 111, in <module>
    asyncio.run(run_dreamer_flow())
  File "C:\Users\thecr\AppData\Local\Programs\Python\Python313\Lib\asyncio\runners.py", line 195, in run
    return runner.run(main)
  File "C:\Users\thecr\AppData\Local\Programs\Python\Python313\Lib\asyncio\runners.py", line 118, in run
    return self._loop.run_until_complete(task)
  File "C:\Users\thecr\AppData\Local\Programs\Python\Python313\Lib\asyncio\base_events.py", line 706, in run_until_complete
    self.run_forever()
  File "C:\Users\thecr\AppData\Local\Programs\Python\Python313\Lib\asyncio\base_events.py", line 677, in run_forever
    self._run_once()
  File "C:\Users\thecr\AppData\Local\Programs\Python\Python313\Lib\asyncio\base_events.py", line 2034, in _run_once
    handle._run()
  File "C:\Users\thecr\AppData\Local\Programs\Python\Python313\Lib\asyncio\events.py", line 89, in _run
    self._context.run(self._callback, *self._args)
  File "C:\DreamerAI\main.py", line 53, in run_dreamer_flow
    agents["Jeff"] = ChefJeff(llm_instance=llm_service, user_dir=DEFAULT_USER_DIR)
  File "C:\DreamerAI\engine\agents\main_chat.py", line 61, in __init__
    super().__init__(name="Jeff", user_dir=data.get("user_dir"), distill=False, llm=llm_instance, **data)
TypeError: engine.agents.base.BaseAgent.__init__() got multiple values for keyword argument 'user_dir'

2025-04-12 00:06:01 | ERROR    | engine.core.workflow:execute:112 - An unexpected error occurred during DreamerFlow execution: ChefJeff.run() got an unexpected keyword argument 'initial_user_input'. Did you mean 'initial_input'?
Traceback (most recent call last):
  File "C:\DreamerAI\main.py", line 111, in <module>
    asyncio.run(run_dreamer_flow())
  File "C:\Users\thecr\AppData\Local\Programs\Python\Python313\Lib\asyncio\runners.py", line 195, in run
    return runner.run(main)
  File "C:\Users\thecr\AppData\Local\Programs\Python\Python313\Lib\asyncio\runners.py", line 118, in run
    return self._loop.run_until_complete(task)
  File "C:\Users\thecr\AppData\Local\Programs\Python\Python313\Lib\asyncio\base_events.py", line 706, in run_until_complete
    self.run_forever()
  File "C:\Users\thecr\AppData\Local\Programs\Python\Python313\Lib\asyncio\base_events.py", line 677, in run_forever
    self._run_once()
  File "C:\Users\thecr\AppData\Local\Programs\Python\Python313\Lib\asyncio\base_events.py", line 2034, in _run_once
    handle._run()
  File "C:\Users\thecr\AppData\Local\Programs\Python\Python313\Lib\asyncio\events.py", line 89, in _run
    self._context.run(self._callback, *self._args)
  File "C:\DreamerAI\main.py", line 90, in run_dreamer_flow
    result = await dreamer_flow.execute(initial_user_input=test_input)
> File "C:\DreamerAI\engine\core\workflow.py", line 86, in execute
    jeff_response = await jeff_agent.run(initial_user_input=initial_user_input) # Changed from guide's user_input to match local var
TypeError: ChefJeff.run() got an unexpected keyword argument 'initial_user_input'. Did you mean 'initial_input'?

Traceback (most recent call last):
  File "C:\DreamerAI\main.py", line 111, in <module>
    asyncio.run(run_dreamer_flow())
  File "C:\Users\thecr\AppData\Local\Programs\Python\Python313\Lib\asyncio\runners.py", line 195, in run
    return runner.run(main)
  File "C:\Users\thecr\AppData\Local\Programs\Python\Python313\Lib\asyncio\runners.py", line 118, in run
    return self._loop.run_until_complete(task)
  File "C:\Users\thecr\AppData\Local\Programs\Python\Python313\Lib\asyncio\base_events.py", line 706, in run_until_complete
    self.run_forever()
  File "C:\Users\thecr\AppData\Local\Programs\Python\Python313\Lib\asyncio\base_events.py", line 677, in run_forever
    self._run_once()
  File "C:\Users\thecr\AppData\Local\Programs\Python\Python313\Lib\asyncio\base_events.py", line 2034, in _run_once
    handle._run()
  File "C:\Users\thecr\AppData\Local\Programs\Python\Python313\Lib\asyncio\events.py", line 89, in _run
    self._context.run(self._callback, *self._args)
  File "C:\DreamerAI\main.py", line 53, in run_dreamer_flow
    agents["Jeff"] = ChefJeff(llm_instance=llm_service, user_dir=DEFAULT_USER_DIR)
  File "C:\DreamerAI\engine\agents\main_chat.py", line 61, in __init__
    super().__init__(name="Jeff", user_dir=data.get("user_dir"), distill=False, llm=llm_instance, **data)
TypeError: engine.agents.base.BaseAgent.__init__() got multiple values for keyword argument 'user_dir'

2025-04-12 00:06:01 | ERROR    | engine.core.workflow:execute:112 - An unexpected error occurred during DreamerFlow execution: ChefJeff.run() got an unexpected keyword argument 'initial_user_input'. Did you mean 'initial_input'?
Traceback (most recent call last):
  File "C:\DreamerAI\main.py", line 111, in <module>
    asyncio.run(run_dreamer_flow())
  File "C:\Users\thecr\AppData\Local\Programs\Python\Python313\Lib\asyncio\runners.py", line 195, in run
    return runner.run(main)
  File "C:\Users\thecr\AppData\Local\Programs\Python\Python313\Lib\asyncio\runners.py", line 118, in run
    return self._loop.run_until_complete(task)
  File "C:\Users\thecr\AppData\Local\Programs\Python\Python313\Lib\asyncio\base_events.py", line 706, in run_until_complete
    self.run_forever()
  File "C:\Users\thecr\AppData\Local\Programs\Python\Python313\Lib\asyncio\base_events.py", line 677, in run_forever
    self._run_once()
  File "C:\Users\thecr\AppData\Local\Programs\Python\Python313\Lib\asyncio\base_events.py", line 2034, in _run_once
    handle._run()
  File "C:\Users\thecr\AppData\Local\Programs\Python\Python313\Lib\asyncio\events.py", line 89, in _run
    self._context.run(self._callback, *self._args)
  File "C:\DreamerAI\main.py", line 90, in run_dreamer_flow
    result = await dreamer_flow.execute(initial_user_input=test_input)
> File "C:\DreamerAI\engine\core\workflow.py", line 86, in execute
    jeff_response = await jeff_agent.run(initial_user_input=initial_user_input) # Changed from guide's user_input to match local var
TypeError: ChefJeff.run() got an unexpected keyword argument 'initial_user_input'. Did you mean 'initial_input'?

Traceback (most recent call last):
  File "C:\DreamerAI\main.py", line 111, in <module>
    asyncio.run(run_dreamer_flow())
  File "C:\Users\thecr\AppData\Local\Programs\Python\Python313\Lib\asyncio\runners.py", line 195, in run
    return runner.run(main)
  File "C:\Users\thecr\AppData\Local\Programs\Python\Python313\Lib\asyncio\runners.py", line 118, in run
    return self._loop.run_until_complete(task)
  File "C:\Users\thecr\AppData\Local\Programs\Python\Python313\Lib\asyncio\base_events.py", line 706, in run_until_complete
    self.run_forever()
  File "C:\Users\thecr\AppData\Local\Programs\Python\Python313\Lib\asyncio\base_events.py", line 677, in run_forever
    self._run_once()
  File "C:\Users\thecr\AppData\Local\Programs\Python\Python313\Lib\asyncio\base_events.py", line 2034, in _run_once
    handle._run()
  File "C:\Users\thecr\AppData\Local\Programs\Python\Python313\Lib\asyncio\events.py", line 89, in _run
    self._context.run(self._callback, *self._args)
  File "C:\DreamerAI\main.py", line 53, in run_dreamer_flow
    agents["Jeff"] = ChefJeff(llm_instance=llm_service, user_dir=DEFAULT_USER_DIR)
  File "C:\DreamerAI\engine\agents\main_chat.py", line 61, in __init__
    super().__init__(name="Jeff", user_dir=data.get("user_dir"), distill=False, llm=llm_instance, **data)
TypeError: engine.agents.base.BaseAgent.__init__() got multiple values for keyword argument 'user_dir'

2025-04-12 00:06:01 | ERROR    | engine.core.workflow:execute:112 - An unexpected error occurred during DreamerFlow execution: ChefJeff.run() got an unexpected keyword argument 'initial_user_input'. Did you mean 'initial_input'?
Traceback (most recent call last):
  File "C:\DreamerAI\main.py", line 111, in <module>
    asyncio.run(run_dreamer_flow())
  File "C:\Users\thecr\AppData\Local\Programs\Python\Python313\Lib\asyncio\runners.py", line 195, in run
    return runner.run(main)
  File "C:\Users\thecr\AppData\Local\Programs\Python\Python313\Lib\asyncio\runners.py", line 118, in run
    return self._loop.run_until_complete(task)
  File "C:\Users\thecr\AppData\Local\Programs\Python\Python313\Lib\asyncio\base_events.py", line 706, in run_until_complete
    self.run_forever()
  File "C:\Users\thecr\AppData\Local\Programs\Python\Python313\Lib\asyncio\base_events.py", line 677, in run_forever
    self._run_once()
  File "C:\Users\thecr\AppData\Local\Programs\Python\Python313\Lib\asyncio\base_events.py", line 2034, in _run_once
    handle._run()
  File "C:\Users\thecr\AppData\Local\Programs\Python\Python313\Lib\asyncio\events.py", line 89, in _run
    self._context.run(self._callback, *self._args)
  File "C:\DreamerAI\main.py", line 90, in run_dreamer_flow
    result = await dreamer_flow.execute(initial_user_input=test_input)
> File "C:\DreamerAI\engine\core\workflow.py", line 86, in execute
    jeff_response = await jeff_agent.run(initial_user_input=initial_user_input) # Changed from guide's user_input to match local var
TypeError: ChefJeff.run() got an unexpected keyword argument 'initial_user_input'. Did you mean 'initial_input'?

Traceback (most recent call last):
  File "C:\DreamerAI\main.py", line 111, in <module>
    asyncio.run(run_dreamer_flow())
  File "C:\Users\thecr\AppData\Local\Programs\Python\Python313\Lib\asyncio\runners.py", line 195, in run
    return runner.run(main)
  File "C:\Users\thecr\AppData\Local\Programs\Python\Python313\Lib\asyncio\runners.py", line 118, in run
    return self._loop.run_until_complete(task)
  File "C:\Users\thecr\AppData\Local\Programs\Python\Python313\Lib\asyncio\base_events.py", line 706, in run_until_complete
    self.run_forever()
  File "C:\Users\thecr\AppData\Local\Programs\Python\Python313\Lib\asyncio\base_events.py", line 677, in run_forever
    self._run_once()
  File "C:\Users\thecr\AppData\Local\Programs\Python\Python313\Lib\asyncio\base_events.py", line 2034, in _run_once
    handle._run()
  File "C:\Users\thecr\AppData\Local\Programs\Python\Python313\Lib\asyncio\events.py", line 89, in _run
    self._context.run(self._callback, *self._args)
  File "C:\DreamerAI\main.py", line 53, in run_dreamer_flow
    agents["Jeff"] = ChefJeff(llm_instance=llm_service, user_dir=DEFAULT_USER_DIR)
  File "C:\DreamerAI\engine\agents\main_chat.py", line 61, in __init__
    super().__init__(name="Jeff", user_dir=data.get("user_dir"), distill=False, llm=llm_instance, **data)
TypeError: engine.agents.base.BaseAgent.__init__() got multiple values for keyword argument 'user_dir'

2025-04-12 00:06:01 | ERROR    | engine.core.workflow:execute:112 - An unexpected error occurred during DreamerFlow execution: ChefJeff.run() got an unexpected keyword argument 'initial_user_input'. Did you mean 'initial_input'?
Traceback (most recent call last):
  File "C:\DreamerAI\main.py", line 111, in <module>
    asyncio.run(run_dreamer_flow())
  File "C:\Users\thecr\AppData\Local\Programs\Python\Python313\Lib\asyncio\runners.py", line 195, in run
    return runner.run(main)
  File "C:\Users\thecr\AppData\Local\Programs\Python\Python313\Lib\asyncio\runners.py", line 118, in run
    return self._loop.run_until_complete(task)
  File "C:\Users\thecr\AppData\Local\Programs\Python\Python313\Lib\asyncio\base_events.py", line 706, in run_until_complete
    self.run_forever()
  File "C:\Users\thecr\AppData\Local\Programs\Python\Python313\Lib\asyncio\base_events.py", line 677, in run_forever
    self._run_once()
  File "C:\Users\thecr\AppData\Local\Programs\Python\Python313\Lib\asyncio\base_events.py", line 2034, in _run_once
    handle._run()
  File "C:\Users\thecr\AppData\Local\Programs\Python\Python313\Lib\asyncio\events.py", line 89, in _run
    self._context.run(self._callback, *self._args)
  File "C:\DreamerAI\main.py", line 90, in run_dreamer_flow
    result = await dreamer_flow.execute(initial_user_input=test_input)
> File "C:\DreamerAI\engine\core\workflow.py", line 86, in execute
    jeff_response = await jeff_agent.run(initial_user_input=initial_user_input) # Changed from guide's user_input to match local var
TypeError: ChefJeff.run() got an unexpected keyword argument 'initial_user_input'. Did you mean 'initial_input'?

Traceback (most recent call last):
  File "C:\DreamerAI\main.py", line 111, in <module>
    asyncio.run(run_dreamer_flow())
  File "C:\Users\thecr\AppData\Local\Programs\Python\Python313\Lib\asyncio\runners.py", line 195, in run
    return runner.run(main)
  File "C:\Users\thecr\AppData\Local\Programs\Python\Python313\Lib\asyncio\runners.py", line 118, in run
    return self._loop.run_until_complete(task)
  File "C:\Users\thecr\AppData\Local\Programs\Python\Python313\Lib\asyncio\base_events.py", line 706, in run_until_complete
    self.run_forever()
  File "C:\Users\thecr\AppData\Local\Programs\Python\Python313\Lib\asyncio\base_events.py", line 677, in run_forever
    self._run_once()
  File "C:\Users\thecr\AppData\Local\Programs\Python\Python313\Lib\asyncio\base_events.py", line 2034, in _run_once
    handle._run()
  File "C:\Users\thecr\AppData\Local\Programs\Python\Python313\Lib\asyncio\events.py", line 89, in _run
    self._context.run(self._callback, *self._args)
  File "C:\DreamerAI\main.py", line 53, in run_dreamer_flow
    agents["Jeff"] = ChefJeff(llm_instance=llm_service, user_dir=DEFAULT_USER_DIR)
  File "C:\DreamerAI\engine\agents\main_chat.py", line 61, in __init__
    super().__init__(name="Jeff", user_dir=data.get("user_dir"), distill=False, llm=llm_instance, **data)
TypeError: engine.agents.base.BaseAgent.__init__() got multiple values for keyword argument 'user_dir'

2025-04-12 00:06:01 | ERROR    | engine.core.workflow:execute:112 - An unexpected error occurred during DreamerFlow execution: ChefJeff.run() got an unexpected keyword argument 'initial_user_input'. Did you mean 'initial_input'?
Traceback (most recent call last):
  File "C:\DreamerAI\main.py", line 111, in <module>
    asyncio.run(run_dreamer_flow())
  File "C:\Users\thecr\AppData\Local\Programs\Python\Python313\Lib\asyncio\runners.py", line 195, in run
    return runner.run(main)
  File "C:\Users\thecr\AppData\Local\Programs\Python\Python313\Lib\asyncio\runners.py", line 118, in run
    return self._loop.run_until_complete(task)
  File "C:\Users\thecr\AppData\Local\Programs\Python\Python313\Lib\asyncio\base_events.py", line 706, in run_until_complete
    self.run_forever()
  File "C:\Users\thecr\AppData\Local\Programs\Python\Python313\Lib\asyncio\base_events.py", line 677, in run_forever
    self._run_once()
  File "C:\Users\thecr\AppData\Local\Programs\Python\Python313\Lib\asyncio\base_events.py", line 2034, in _run_once
    handle._run()
  File "C:\Users\thecr\AppData\Local\Programs\Python\Python313\Lib\asyncio\events.py", line 89, in _run
    self._context.run(self._callback, *self._args)
  File "C:\DreamerAI\main.py", line 90, in run_dreamer_flow
    result = await dreamer_flow.execute(initial_user_input=test_input)
> File "C:\DreamerAI\engine\core\workflow.py", line 86, in execute
    jeff_response = await jeff_agent.run(initial_user_input=initial_user_input) # Changed from guide's user_input to match local var
TypeError: ChefJeff.run() got an unexpected keyword argument 'initial_user_input'. Did you mean 'initial_input'?

Traceback (most recent call last):
  File "C:\DreamerAI\main.py", line 111, in <module>
    asyncio.run(run_dreamer_flow())
  File "C:\Users\thecr\AppData\Local\Programs\Python\Python313\Lib\asyncio\runners.py", line 195, in run
    return runner.run(main)
  File "C:\Users\thecr\AppData\Local\Programs\Python\Python313\Lib\asyncio\runners.py", line 118, in run
    return self._loop.run_until_complete(task)
  File "C:\Users\thecr\AppData\Local\Programs\Python\Python313\Lib\asyncio\base_events.py", line 706, in run_until_complete
    self.run_forever()
  File "C:\Users\thecr\AppData\Local\Programs\Python\Python313\Lib\asyncio\base_events.py", line 677, in run_forever
    self._run_once()
  File "C:\Users\thecr\AppData\Local\Programs\Python\Python313\Lib\asyncio\base_events.py", line 2034, in _run_once
    handle._run()
  File "C:\Users\thecr\AppData\Local\Programs\Python\Python313\Lib\asyncio\events.py", line 89, in _run
    self._context.run(self._callback, *self._args)
  File "C:\DreamerAI\main.py", line 53, in run_dreamer_flow
    agents["Jeff"] = ChefJeff(llm_instance=llm_service, user_dir=DEFAULT_USER_DIR)
  File "C:\DreamerAI\engine\agents\main_chat.py", line 61, in __init__
    super().__init__(name="Jeff", user_dir=data.get("user_dir"), distill=False, llm=llm_instance, **data)
TypeError: engine.agents.base.BaseAgent.__init__() got multiple values for keyword argument 'user_dir'

2025-04-12 00:06:01 | ERROR    | engine.core.workflow:execute:112 - An unexpected error occurred during DreamerFlow execution: ChefJeff.run() got an unexpected keyword argument 'initial_user_input'. Did you mean 'initial_input'?
Traceback (most recent call last):
  File "C:\DreamerAI\main.py", line 111, in <module>
    asyncio.run(run_dreamer_flow())
  File "C:\Users\thecr\AppData\Local\Programs\Python\Python313\Lib\asyncio\runners.py", line 195, in run
    return runner.run(main)
  File "C:\Users\thecr\AppData\Local\Programs\Python\Python313\Lib\asyncio\runners.py", line 118, in run
    return self._loop.run_until_complete(task)
  File "C:\Users\thecr\AppData\Local\Programs\Python\Python313\Lib\asyncio\base_events.py", line 706, in run_until_complete
    self.run_forever()
  File "C:\Users\thecr\AppData\Local\Programs\Python\Python313\Lib\asyncio\base_events.py", line 677, in run_forever
    self._run_once()
  File "C:\Users\thecr\AppData\Local\Programs\Python\Python313\Lib\asyncio\base_events.py", line 2034, in _run_once
    handle._run()
  File "C:\Users\thecr\AppData\Local\Programs\Python\Python313\Lib\asyncio\events.py", line 89, in _run
    self._context.run(self._callback, *self._args)
  File "C:\DreamerAI\main.py", line 90, in run_dreamer_flow
    result = await dreamer_flow.execute(initial_user_input=test_input)
> File "C:\DreamerAI\engine\core\workflow.py", line 86, in execute
    jeff_response = await jeff_agent.run(initial_user_input=initial_user_input) # Changed from guide's user_input to match local var
TypeError: ChefJeff.run() got an unexpected keyword argument 'initial_user_input'. Did you mean 'initial_input'?

Traceback (most recent call last):
  File "C:\DreamerAI\main.py", line 111, in <module>
    asyncio.run(run_dreamer_flow())
  File "C:\Users\thecr\AppData\Local\Programs\Python\Python313\Lib\asyncio\runners.py", line 195, in run
    return runner.run(main)
  File "C:\Users\thecr\AppData\Local\Programs\Python\Python313\Lib\asyncio\runners.py", line 118, in run
    return self._loop.run_until_complete(task)
  File "C:\Users\thecr\AppData\Local\Programs\Python\Python313\Lib\asyncio\base_events.py", line 706, in run_until_complete
    self.run_forever()
  File "C:\Users\thecr\AppData\Local\Programs\Python\Python313\Lib\asyncio\base_events.py", line 677, in run_forever
    self._run_once()
  File "C:\Users\thecr\AppData\Local\Programs\Python\Python313\Lib\asyncio\base_events.py", line 2034, in _run_once
    handle._run()
  File "C:\Users\thecr\AppData\Local\Programs\Python\Python313\Lib\asyncio\events.py", line 89, in _run
    self._context.run(self._callback, *self._args)
  File "C:\DreamerAI\main.py", line 53, in run_dreamer_flow
    agents["Jeff"] = ChefJeff(llm_instance=llm_service, user_dir=DEFAULT_USER_DIR)
  File "C:\DreamerAI\engine\agents\main_chat.py", line 61, in __init__
    super().__init__(name="Jeff", user_dir=data.get("user_dir"), distill=False, llm=llm_instance, **data)
TypeError: engine.agents.base.BaseAgent.__init__() got multiple values for keyword argument 'user_dir'

2025-04-12 00:06:01 | ERROR    | engine.core.workflow:execute:112 - An unexpected error occurred during DreamerFlow execution: ChefJeff.run() got an unexpected keyword argument 'initial_user_input'. Did you mean 'initial_input'?
Traceback (most recent call last):
  File "C:\DreamerAI\main.py", line 111, in <module>
    asyncio.run(run_dreamer_flow())
  File "C:\Users\thecr\AppData\Local\Programs\Python\Python313\Lib\asyncio\runners.py", line 195, in run
    return runner.run(main)
  File "C:\Users\thecr\AppData\Local\Programs\Python\Python313\Lib\asyncio\runners.py", line 118, in run
    return self._loop.run_until_complete(task)
  File "C:\Users\thecr\AppData\Local\Programs\Python\Python313\Lib\asyncio\base_events.py", line 706, in run_until_complete
    self.run_forever()
  File "C:\Users\thecr\AppData\Local\Programs\Python\Python313\Lib\asyncio\base_events.py", line 677, in run_forever
    self._run_once()
  File "C:\Users\thecr\AppData\Local\Programs\Python\Python313\Lib\asyncio\base_events.py", line 2034, in _run_once
    handle._run()
  File "C:\Users\thecr\AppData\Local\Programs\Python\Python313\Lib\asyncio\events.py", line 89, in _run
    self._context.run(self._callback, *self._args)
  File "C:\DreamerAI\main.py", line 90, in run_dreamer_flow
    result = await dreamer_flow.execute(initial_user_input=test_input)
> File "C:\DreamerAI\engine\core\workflow.py", line 86, in execute
    jeff_response = await jeff_agent.run(initial_user_input=initial_user_input) # Changed from guide's user_input to match local var
TypeError: ChefJeff.run() got an unexpected keyword argument 'initial_user_input'. Did you mean 'initial_input'?

Traceback (most recent call last):
  File "C:\DreamerAI\main.py", line 111, in <module>
    asyncio.run(run_dreamer_flow())
  File "C:\Users\thecr\AppData\Local\Programs\Python\Python313\Lib\asyncio\runners.py", line 195, in run
    return runner.run(main)
  File "C:\Users\thecr\AppData\Local\Programs\Python\Python313\Lib\asyncio\runners.py", line 118, in run
    return self._loop.run_until_complete(task)
  File "C:\Users\thecr\AppData\Local\Programs\Python\Python313\Lib\asyncio\base_events.py", line 706, in run_until_complete
    self.run_forever()
  File "C:\Users\thecr\AppData\Local\Programs\Python\Python313\Lib\asyncio\base_events.py", line 677, in run_forever
    self._run_once()
  File "C:\Users\thecr\AppData\Local\Programs\Python\Python313\Lib\asyncio\base_events.py", line 2034, in _run_once
    handle._run()
  File "C:\Users\thecr\AppData\Local\Programs\Python\Python313\Lib\asyncio\events.py", line 89, in _run
    self._context.run(self._callback, *self._args)
  File "C:\DreamerAI\main.py", line 53, in run_dreamer_flow
    agents["Jeff"] = ChefJeff(llm_instance=llm_service, user_dir=DEFAULT_USER_DIR)
  File "C:\DreamerAI\engine\agents\main_chat.py", line 61, in __init__
    super().__init__(name="Jeff", user_dir=data.get("user_dir"), distill=False, llm=llm_instance, **data)
TypeError: engine.agents.base.BaseAgent.__init__() got multiple values for keyword argument 'user_dir'

2025-04-12 00:06:01 | ERROR    | engine.core.workflow:execute:112 - An unexpected error occurred during DreamerFlow execution: ChefJeff.run() got an unexpected keyword argument 'initial_user_input'. Did you mean 'initial_input'?
Traceback (most recent call last):
  File "C:\DreamerAI\main.py", line 111, in <module>
    asyncio.run(run_dreamer_flow())
  File "C:\Users\thecr\AppData\Local\Programs\Python\Python313\Lib\asyncio\runners.py", line 195, in run
    return runner.run(main)
  File "C:\Users\thecr\AppData\Local\Programs\Python\Python313\Lib\asyncio\runners.py", line 118, in run
    return self._loop.run_until_complete(task)
  File "C:\Users\thecr\AppData\Local\Programs\Python\Python313\Lib\asyncio\base_events.py", line 706, in run_until_complete
    self.run_forever()
  File "C:\Users\thecr\AppData\Local\Programs\Python\Python313\Lib\asyncio\base_events.py", line 677, in run_forever
    self._run_once()
  File "C:\Users\thecr\AppData\Local\Programs\Python\Python313\Lib\asyncio\base_events.py", line 2034, in _run_once
    handle._run()
  File "C:\Users\thecr\AppData\Local\Programs\Python\Python313\Lib\asyncio\events.py", line 89, in _run
    self._context.run(self._callback, *self._args)
  File "C:\DreamerAI\main.py", line 90, in run_dreamer_flow
    result = await dreamer_flow.execute(initial_user_input=test_input)
> File "C:\DreamerAI\engine\core\workflow.py", line 86, in execute
    jeff_response = await jeff_agent.run(initial_user_input=initial_user_input) # Changed from guide's user_input to match local var
TypeError: ChefJeff.run() got an unexpected keyword argument 'initial_user_input'. Did you mean 'initial_input'?

Traceback (most recent call last):
  File "C:\DreamerAI\main.py", line 111, in <module>
    asyncio.run(run_dreamer_flow())
  File "C:\Users\thecr\AppData\Local\Programs\Python\Python313\Lib\asyncio\runners.py", line 195, in run
    return runner.run(main)
  File "C:\Users\thecr\AppData\Local\Programs\Python\Python313\Lib\asyncio\runners.py", line 118, in run
    return self._loop.run_until_complete(task)
  File "C:\Users\thecr\AppData\Local\Programs\Python\Python313\Lib\asyncio\base_events.py", line 706, in run_until_complete
    self.run_forever()
  File "C:\Users\thecr\AppData\Local\Programs\Python\Python313\Lib\asyncio\base_events.py", line 677, in run_forever
    self._run_once()
  File "C:\Users\thecr\AppData\Local\Programs\Python\Python313\Lib\asyncio\base_events.py", line 2034, in _run_once
    handle._run()
  File "C:\Users\thecr\AppData\Local\Programs\Python\Python313\Lib\asyncio\events.py", line 89, in _run
    self._context.run(self._callback, *self._args)
  File "C:\DreamerAI\main.py", line 53, in run_dreamer_flow
    agents["Jeff"] = ChefJeff(llm_instance=llm_service, user_dir=DEFAULT_USER_DIR)
  File "C:\DreamerAI\engine\agents\main_chat.py", line 61, in __init__
    super().__init__(name="Jeff", user_dir=data.get("user_dir"), distill=False, llm=llm_instance, **data)
TypeError: engine.agents.base.BaseAgent.__init__() got multiple values for keyword argument 'user_dir'

2025-04-12 00:06:01 | ERROR    | engine.core.workflow:execute:112 - An unexpected error occurred during DreamerFlow execution: ChefJeff.run() got an unexpected keyword argument 'initial_user_input'. Did you mean 'initial_input'?
Traceback (most recent call last):
  File "C:\DreamerAI\main.py", line 111, in <module>
    asyncio.run(run_dreamer_flow())
  File "C:\Users\thecr\AppData\Local\Programs\Python\Python313\Lib\asyncio\runners.py", line 195, in run
    return runner.run(main)
  File "C:\Users\thecr\AppData\Local\Programs\Python\Python313\Lib\asyncio\runners.py", line 118, in run
    return self._loop.run_until_complete(task)
  File "C:\Users\thecr\AppData\Local\Programs\Python\Python313\Lib\asyncio\base_events.py", line 706, in run_until_complete
    self.run_forever()
  File "C:\Users\thecr\AppData\Local\Programs\Python\Python313\Lib\asyncio\base_events.py", line 677, in run_forever
    self._run_once()
  File "C:\Users\thecr\AppData\Local\Programs\Python\Python313\Lib\asyncio\base_events.py", line 2034, in _run_once
    handle._run()
  File "C:\Users\thecr\AppData\Local\Programs\Python\Python313\Lib\asyncio\events.py", line 89, in _run
    self._context.run(self._callback, *self._args)
  File "C:\DreamerAI\main.py", line 90, in run_dreamer_flow
    result = await dreamer_flow.execute(initial_user_input=test_input)
> File "C:\DreamerAI\engine\core\workflow.py", line 86, in execute
    jeff_response = await jeff_agent.run(initial_user_input=initial_user_input) # Changed from guide's user_input to match local var
TypeError: ChefJeff.run() got an unexpected keyword argument 'initial_user_input'. Did you mean 'initial_input'?

Traceback (most recent call last):
  File "C:\DreamerAI\main.py", line 111, in <module>
    asyncio.run(run_dreamer_flow())
  File "C:\Users\thecr\AppData\Local\Programs\Python\Python313\Lib\asyncio\runners.py", line 195, in run
    return runner.run(main)
  File "C:\Users\thecr\AppData\Local\Programs\Python\Python313\Lib\asyncio\runners.py", line 118, in run
    return self._loop.run_until_complete(task)
  File "C:\Users\thecr\AppData\Local\Programs\Python\Python313\Lib\asyncio\base_events.py", line 706, in run_until_complete
    self.run_forever()
  File "C:\Users\thecr\AppData\Local\Programs\Python\Python313\Lib\asyncio\base_events.py", line 677, in run_forever
    self._run_once()
  File "C:\Users\thecr\AppData\Local\Programs\Python\Python313\Lib\asyncio\base_events.py", line 2034, in _run_once
    handle._run()
  File "C:\Users\thecr\AppData\Local\Programs\Python\Python313\Lib\asyncio\events.py", line 89, in _run
    self._context.run(self._callback, *self._args)
  File "C:\DreamerAI\main.py", line 53, in run_dreamer_flow
    agents["Jeff"] = ChefJeff(llm_instance=llm_service, user_dir=DEFAULT_USER_DIR)
  File "C:\DreamerAI\engine\agents\main_chat.py", line 61, in __init__
    super().__init__(name="Jeff", user_dir=data.get("user_dir"), distill=False, llm=llm_instance, **data)
TypeError: engine.agents.base.BaseAgent.__init__() got multiple values for keyword argument 'user_dir'

2025-04-12 00:06:01 | ERROR    | engine.core.workflow:execute:112 - An unexpected error occurred during DreamerFlow execution: ChefJeff.run() got an unexpected keyword argument 'initial_user_input'. Did you mean 'initial_input'?
Traceback (most recent call last):
  File "C:\DreamerAI\main.py", line 111, in <module>
    asyncio.run(run_dreamer_flow())
  File "C:\Users\thecr\AppData\Local\Programs\Python\Python313\Lib\asyncio\runners.py", line 195, in run
    return runner.run(main)
  File "C:\Users\thecr\AppData\Local\Programs\Python\Python313\Lib\asyncio\runners.py", line 118, in run
    return self._loop.run_until_complete(task)
  File "C:\Users\thecr\AppData\Local\Programs\Python\Python313\Lib\asyncio\base_events.py", line 706, in run_until_complete
    self.run_forever()
  File "C:\Users\thecr\AppData\Local\Programs\Python\Python313\Lib\asyncio\base_events.py", line 677, in run_forever
    self._run_once()
  File "C:\Users\thecr\AppData\Local\Programs\Python\Python313\Lib\asyncio\base_events.py", line 2034, in _run_once
    handle._run()
  File "C:\Users\thecr\AppData\Local\Programs\Python\Python313\Lib\asyncio\events.py", line 89, in _run
    self._context.run(self._callback, *self._args)
  File "C:\DreamerAI\main.py", line 90, in run_dreamer_flow
    result = await dreamer_flow.execute(initial_user_input=test_input)
> File "C:\DreamerAI\engine\core\workflow.py", line 86, in execute
    jeff_response = await jeff_agent.run(initial_user_input=initial_user_input) # Changed from guide's user_input to match local var
TypeError: ChefJeff.run() got an unexpected keyword argument 'initial_user_input'. Did you mean 'initial_input'?

Traceback (most recent call last):
  File "C:\DreamerAI\main.py", line 111, in <module>
    asyncio.run(run_dreamer_flow())
  File "C:\Users\thecr\AppData\Local\Programs\Python\Python313\Lib\asyncio\runners.py", line 195, in run
    return runner.run(main)
  File "C:\Users\thecr\AppData\Local\Programs\Python\Python313\Lib\asyncio\runners.py", line 118, in run
    return self._loop.run_until_complete(task)
  File "C:\Users\thecr\AppData\Local\Programs\Python\Python313\Lib\asyncio\base_events.py", line 706, in run_until_complete
    self.run_forever()
  File "C:\Users\thecr\AppData\Local\Programs\Python\Python313\Lib\asyncio\base_events.py", line 677, in run_forever
    self._run_once()
  File "C:\Users\thecr\AppData\Local\Programs\Python\Python313\Lib\asyncio\base_events.py", line 2034, in _run_once
    handle._run()
  File "C:\Users\thecr\AppData\Local\Programs\Python\Python313\Lib\asyncio\events.py", line 89, in _run
    self._context.run(self._callback, *self._args)
  File "C:\DreamerAI\main.py", line 53, in run_dreamer_flow
    agents["Jeff"] = ChefJeff(llm_instance=llm_service, user_dir=DEFAULT_USER_DIR)
  File "C:\DreamerAI\engine\agents\main_chat.py", line 61, in __init__
    super().__init__(name="Jeff", user_dir=data.get("user_dir"), distill=False, llm=llm_instance, **data)
TypeError: engine.agents.base.BaseAgent.__init__() got multiple values for keyword argument 'user_dir'

2025-04-12 00:06:01 | ERROR    | engine.core.workflow:execute:112 - An unexpected error occurred during DreamerFlow execution: ChefJeff.run() got an unexpected keyword argument 'initial_user_input'. Did you mean 'initial_input'?
Traceback (most recent call last):
  File "C:\DreamerAI\main.py", line 111, in <module>
    asyncio.run(run_dreamer_flow())
  File "C:\Users\thecr\AppData\Local\Programs\Python\Python313\Lib\asyncio\runners.py", line 195, in run
    return runner.run(main)
  File "C:\Users\thecr\AppData\Local\Programs\Python\Python313\Lib\asyncio\runners.py", line 118, in run
    return self._loop.run_until_complete(task)
  File "C:\Users\thecr\AppData\Local\Programs\Python\Python313\Lib\asyncio\base_events.py", line 706, in run_until_complete
    self.run_forever()
  File "C:\Users\thecr\AppData\Local\Programs\Python\Python313\Lib\asyncio\base_events.py", line 677, in run_forever
    self._run_once()
  File "C:\Users\thecr\AppData\Local\Programs\Python\Python313\Lib\asyncio\base_events.py", line 2034, in _run_once
    handle._run()
  File "C:\Users\thecr\AppData\Local\Programs\Python\Python313\Lib\asyncio\events.py", line 89, in _run
    self._context.run(self._callback, *self._args)
  File "C:\DreamerAI\main.py", line 90, in run_dreamer_flow
    result = await dreamer_flow.execute(initial_user_input=test_input)
> File "C:\DreamerAI\engine\core\workflow.py", line 86, in execute
    jeff_response = await jeff_agent.run(initial_user_input=initial_user_input) # Changed from guide's user_input to match local var
TypeError: ChefJeff.run() got an unexpected keyword argument 'initial_user_input'. Did you mean 'initial_input'?

Traceback (most recent call last):
  File "C:\DreamerAI\main.py", line 111, in <module>
    asyncio.run(run_dreamer_flow())
  File "C:\Users\thecr\AppData\Local\Programs\Python\Python313\Lib\asyncio\runners.py", line 195, in run
    return runner.run(main)
  File "C:\Users\thecr\AppData\Local\Programs\Python\Python313\Lib\asyncio\runners.py", line 118, in run
    return self._loop.run_until_complete(task)
  File "C:\Users\thecr\AppData\Local\Programs\Python\Python313\Lib\asyncio\base_events.py", line 706, in run_until_complete
    self.run_forever()
  File "C:\Users\thecr\AppData\Local\Programs\Python\Python313\Lib\asyncio\base_events.py", line 677, in run_forever
    self._run_once()
  File "C:\Users\thecr\AppData\Local\Programs\Python\Python313\Lib\asyncio\base_events.py", line 2034, in _run_once
    handle._run()
  File "C:\Users\thecr\AppData\Local\Programs\Python\Python313\Lib\asyncio\events.py", line 89, in _run
    self._context.run(self._callback, *self._args)
  File "C:\DreamerAI\main.py", line 53, in run_dreamer_flow
    agents["Jeff"] = ChefJeff(llm_instance=llm_service, user_dir=DEFAULT_USER_DIR)
  File "C:\DreamerAI\engine\agents\main_chat.py", line 61, in __init__
    super().__init__(name="Jeff", user_dir=data.get("user_dir"), distill=False, llm=llm_instance, **data)
TypeError: engine.agents.base.BaseAgent.__init__() got multiple values for keyword argument 'user_dir'

2025-04-12 00:06:01 | ERROR    | engine.core.workflow:execute:112 - An unexpected error occurred during DreamerFlow execution: ChefJeff.run() got an unexpected keyword argument 'initial_user_input'. Did you mean 'initial_input'?
Traceback (most recent call last):
  File "C:\DreamerAI\main.py", line 111, in <module>
    asyncio.run(run_dreamer_flow())
  File "C:\Users\thecr\AppData\Local\Programs\Python\Python313\Lib\asyncio\runners.py", line 195, in run
    return runner.run(main)
  File "C:\Users\thecr\AppData\Local\Programs\Python\Python313\Lib\asyncio\runners.py", line 118, in run
    return self._loop.run_until_complete(task)
  File "C:\Users\thecr\AppData\Local\Programs\Python\Python313\Lib\asyncio\base_events.py", line 706, in run_until_complete
    self.run_forever()
  File "C:\Users\thecr\AppData\Local\Programs\Python\Python313\Lib\asyncio\base_events.py", line 677, in run_forever
    self._run_once()
  File "C:\Users\thecr\AppData\Local\Programs\Python\Python313\Lib\asyncio\base_events.py", line 2034, in _run_once
    handle._run()
  File "C:\Users\thecr\AppData\Local\Programs\Python\Python313\Lib\asyncio\events.py", line 89, in _run
    self._context.run(self._callback, *self._args)
  File "C:\DreamerAI\main.py", line 90, in run_dreamer_flow
    result = await dreamer_flow.execute(initial_user_input=test_input)
> File "C:\DreamerAI\engine\core\workflow.py", line 86, in execute
    jeff_response = await jeff_agent.run(initial_user_input=initial_user_input) # Changed from guide's user_input to match local var
TypeError: ChefJeff.run() got an unexpected keyword argument 'initial_user_input'. Did you mean 'initial_input'?

Traceback (most recent call last):
  File "C:\DreamerAI\main.py", line 111, in <module>
    asyncio.run(run_dreamer_flow())
  File "C:\Users\thecr\AppData\Local\Programs\Python\Python313\Lib\asyncio\runners.py", line 195, in run
    return runner.run(main)
  File "C:\Users\thecr\AppData\Local\Programs\Python\Python313\Lib\asyncio\runners.py", line 118, in run
    return self._loop.run_until_complete(task)
  File "C:\Users\thecr\AppData\Local\Programs\Python\Python313\Lib\asyncio\base_events.py", line 706, in run_until_complete
    self.run_forever()
  File "C:\Users\thecr\AppData\Local\Programs\Python\Python313\Lib\asyncio\base_events.py", line 677, in run_forever
    self._run_once()
  File "C:\Users\thecr\AppData\Local\Programs\Python\Python313\Lib\asyncio\base_events.py", line 2034, in _run_once
    handle._run()
  File "C:\Users\thecr\AppData\Local\Programs\Python\Python313\Lib\asyncio\events.py", line 89, in _run
    self._context.run(self._callback, *self._args)
  File "C:\DreamerAI\main.py", line 53, in run_dreamer_flow
    agents["Jeff"] = ChefJeff(llm_instance=llm_service, user_dir=DEFAULT_USER_DIR)
  File "C:\DreamerAI\engine\agents\main_chat.py", line 61, in __init__
    super().__init__(name="Jeff", user_dir=data.get("user_dir"), distill=False, llm=llm_instance, **data)
TypeError: engine.agents.base.BaseAgent.__init__() got multiple values for keyword argument 'user_dir'

2025-04-12 00:06:01 | ERROR    | engine.core.workflow:execute:112 - An unexpected error occurred during DreamerFlow execution: ChefJeff.run() got an unexpected keyword argument 'initial_user_input'. Did you mean 'initial_input'?
Traceback (most recent call last):
  File "C:\DreamerAI\main.py", line 111, in <module>
    asyncio.run(run_dreamer_flow())
  File "C:\Users\thecr\AppData\Local\Programs\Python\Python313\Lib\asyncio\runners.py", line 195, in run
    return runner.run(main)
  File "C:\Users\thecr\AppData\Local\Programs\Python\Python313\Lib\asyncio\runners.py", line 118, in run
    return self._loop.run_until_complete(task)
  File "C:\Users\thecr\AppData\Local\Programs\Python\Python313\Lib\asyncio\base_events.py", line 706, in run_until_complete
    self.run_forever()
  File "C:\Users\thecr\AppData\Local\Programs\Python\Python313\Lib\asyncio\base_events.py", line 677, in run_forever
    self._run_once()
  File "C:\Users\thecr\AppData\Local\Programs\Python\Python313\Lib\asyncio\base_events.py", line 2034, in _run_once
    handle._run()
  File "C:\Users\thecr\AppData\Local\Programs\Python\Python313\Lib\asyncio\events.py", line 89, in _run
    self._context.run(self._callback, *self._args)
  File "C:\DreamerAI\main.py", line 90, in run_dreamer_flow
    result = await dreamer_flow.execute(initial_user_input=test_input)
> File "C:\DreamerAI\engine\core\workflow.py", line 86, in execute
    jeff_response = await jeff_agent.run(initial_user_input=initial_user_input) # Changed from guide's user_input to match local var
TypeError: ChefJeff.run() got an unexpected keyword argument 'initial_user_input'. Did you mean 'initial_input'?

Traceback (most recent call last):
  File "C:\DreamerAI\main.py", line 111, in <module>
    asyncio.run(run_dreamer_flow())
  File "C:\Users\thecr\AppData\Local\Programs\Python\Python313\Lib\asyncio\runners.py", line 195, in run
    return runner.run(main)
  File "C:\Users\thecr\AppData\Local\Programs\Python\Python313\Lib\asyncio\runners.py", line 118, in run
    return self._loop.run_until_complete(task)
  File "C:\Users\thecr\AppData\Local\Programs\Python\Python313\Lib\asyncio\base_events.py", line 706, in run_until_complete
    self.run_forever()
  File "C:\Users\thecr\AppData\Local\Programs\Python\Python313\Lib\asyncio\base_events.py", line 677, in run_forever
    self._run_once()
  File "C:\Users\thecr\AppData\Local\Programs\Python\Python313\Lib\asyncio\base_events.py", line 2034, in _run_once
    handle._run()
  File "C:\Users\thecr\AppData\Local\Programs\Python\Python313\Lib\asyncio\events.py", line 89, in _run
    self._context.run(self._callback, *self._args)
  File "C:\DreamerAI\main.py", line 53, in run_dreamer_flow
    agents["Jeff"] = ChefJeff(llm_instance=llm_service, user_dir=DEFAULT_USER_DIR)
  File "C:\DreamerAI\engine\agents\main_chat.py", line 61, in __init__
    super().__init__(name="Jeff", user_dir=data.get("user_dir"), distill=False, llm=llm_instance, **data)
TypeError: engine.agents.base.BaseAgent.__init__() got multiple values for keyword argument 'user_dir'

2025-04-12 00:06:01 | ERROR    | engine.core.workflow:execute:112 - An unexpected error occurred during DreamerFlow execution: ChefJeff.run() got an unexpected keyword argument 'initial_user_input'. Did you mean 'initial_input'?
Traceback (most recent call last):
  File "C:\DreamerAI\main.py", line 111, in <module>
    asyncio.run(run_dreamer_flow())
  File "C:\Users\thecr\AppData\Local\Programs\Python\Python313\Lib\asyncio\runners.py", line 195, in run
    return runner.run(main)
  File "C:\Users\thecr\AppData\Local\Programs\Python\Python313\Lib\asyncio\runners.py", line 118, in run
    return self._loop.run_until_complete(task)
  File "C:\Users\thecr\AppData\Local\Programs\Python\Python313\Lib\asyncio\base_events.py", line 706, in run_until_complete
    self.run_forever()
  File "C:\Users\thecr\AppData\Local\Programs\Python\Python313\Lib\asyncio\base_events.py", line 677, in run_forever
    self._run_once()
  File "C:\Users\thecr\AppData\Local\Programs\Python\Python313\Lib\asyncio\base_events.py", line 2034, in _run_once
    handle._run()
  File "C:\Users\thecr\AppData\Local\Programs\Python\Python313\Lib\asyncio\events.py", line 89, in _run
    self._context.run(self._callback, *self._args)
  File "C:\DreamerAI\main.py", line 90, in run_dreamer_flow
    result = await dreamer_flow.execute(initial_user_input=test_input)
> File "C:\DreamerAI\engine\core\workflow.py", line 86, in execute
    jeff_response = await jeff_agent.run(initial_user_input=initial_user_input) # Changed from guide's user_input to match local var
TypeError: ChefJeff.run() got an unexpected keyword argument 'initial_user_input'. Did you mean 'initial_input'?

Traceback (most recent call last):
  File "C:\DreamerAI\main.py", line 111, in <module>
    asyncio.run(run_dreamer_flow())
  File "C:\Users\thecr\AppData\Local\Programs\Python\Python313\Lib\asyncio\runners.py", line 195, in run
    return runner.run(main)
  File "C:\Users\thecr\AppData\Local\Programs\Python\Python313\Lib\asyncio\runners.py", line 118, in run
    return self._loop.run_until_complete(task)
  File "C:\Users\thecr\AppData\Local\Programs\Python\Python313\Lib\asyncio\base_events.py", line 706, in run_until_complete
    self.run_forever()
  File "C:\Users\thecr\AppData\Local\Programs\Python\Python313\Lib\asyncio\base_events.py", line 677, in run_forever
    self._run_once()
  File "C:\Users\thecr\AppData\Local\Programs\Python\Python313\Lib\asyncio\base_events.py", line 2034, in _run_once
    handle._run()
  File "C:\Users\thecr\AppData\Local\Programs\Python\Python313\Lib\asyncio\events.py", line 89, in _run
    self._context.run(self._callback, *self._args)
  File "C:\DreamerAI\main.py", line 53, in run_dreamer_flow
    agents["Jeff"] = ChefJeff(llm_instance=llm_service, user_dir=DEFAULT_USER_DIR)
  File "C:\DreamerAI\engine\agents\main_chat.py", line 61, in __init__
    super().__init__(name="Jeff", user_dir=data.get("user_dir"), distill=False, llm=llm_instance, **data)
TypeError: engine.agents.base.BaseAgent.__init__() got multiple values for keyword argument 'user_dir'

2025-04-12 00:06:01 | ERROR    | engine.core.workflow:execute:112 - An unexpected error occurred during DreamerFlow execution: ChefJeff.run() got an unexpected keyword argument 'initial_user_input'. Did you mean 'initial_input'?
Traceback (most recent call last):
  File "C:\DreamerAI\main.py", line 111, in <module>
    asyncio.run(run_dreamer_flow())
  File "C:\Users\thecr\AppData\Local\Programs\Python\Python313\Lib\asyncio\runners.py", line 195, in run
    return runner.run(main)
  File "C:\Users\thecr\AppData\Local\Programs\Python\Python313\Lib\asyncio\runners.py", line 118, in run
    return self._loop.run_until_complete(task)
  File "C:\Users\thecr\AppData\Local\Programs\Python\Python313\Lib\asyncio\base_events.py", line 706, in run_until_complete
    self.run_forever()
  File "C:\Users\thecr\AppData\Local\Programs\Python\Python313\Lib\asyncio\base_events.py", line 677, in run_forever
    self._run_once()
  File "C:\Users\thecr\AppData\Local\Programs\Python\Python313\Lib\asyncio\base_events.py", line 2034, in _run_once
    handle._run()
  File "C:\Users\thecr\AppData\Local\Programs\Python\Python313\Lib\asyncio\events.py", line 89, in _run
    self._context.run(self._callback, *self._args)
  File "C:\DreamerAI\main.py", line 90, in run_dreamer_flow
    result = await dreamer_flow.execute(initial_user_input=test_input)
> File "C:\DreamerAI\engine\core\workflow.py", line 86, in execute
    jeff_response = await jeff_agent.run(initial_user_input=initial_user_input) # Changed from guide's user_input to match local var
TypeError: ChefJeff.run() got an unexpected keyword argument 'initial_user_input'. Did you mean 'initial_input'?

Traceback (most recent call last):
  File "C:\DreamerAI\main.py", line 111, in <module>
    asyncio.run(run_dreamer_flow())
  File "C:\Users\thecr\AppData\Local\Programs\Python\Python313\Lib\asyncio\runners.py", line 195, in run
    return runner.run(main)
  File "C:\Users\thecr\AppData\Local\Programs\Python\Python313\Lib\asyncio\runners.py", line 118, in run
    return self._loop.run_until_complete(task)
  File "C:\Users\thecr\AppData\Local\Programs\Python\Python313\Lib\asyncio\base_events.py", line 706, in run_until_complete
    self.run_forever()
  File "C:\Users\thecr\AppData\Local\Programs\Python\Python313\Lib\asyncio\base_events.py", line 677, in run_forever
    self._run_once()
  File "C:\Users\thecr\AppData\Local\Programs\Python\Python313\Lib\asyncio\base_events.py", line 2034, in _run_once
    handle._run()
  File "C:\Users\thecr\AppData\Local\Programs\Python\Python313\Lib\asyncio\events.py", line 89, in _run
    self._context.run(self._callback, *self._args)
  File "C:\DreamerAI\main.py", line 53, in run_dreamer_flow
    agents["Jeff"] = ChefJeff(llm_instance=llm_service, user_dir=DEFAULT_USER_DIR)
  File "C:\DreamerAI\engine\agents\main_chat.py", line 61, in __init__
    super().__init__(name="Jeff", user_dir=data.get("user_dir"), distill=False, llm=llm_instance, **data)
TypeError: engine.agents.base.BaseAgent.__init__() got multiple values for keyword argument 'user_dir'

2025-04-12 00:06:01 | ERROR    | engine.core.workflow:execute:112 - An unexpected error occurred during DreamerFlow execution: ChefJeff.run() got an unexpected keyword argument 'initial_user_input'. Did you mean 'initial_input'?
Traceback (most recent call last):
  File "C:\DreamerAI\main.py", line 111, in <module>
    asyncio.run(run_dreamer_flow())
  File "C:\Users\thecr\AppData\Local\Programs\Python\Python313\Lib\asyncio\runners.py", line 195, in run
    return runner.run(main)
  File "C:\Users\thecr\AppData\Local\Programs\Python\Python313\Lib\asyncio\runners.py", line 118, in run
    return self._loop.run_until_complete(task)
  File "C:\Users\thecr\AppData\Local\Programs\Python\Python313\Lib\asyncio\base_events.py", line 706, in run_until_complete
    self.run_forever()
  File "C:\Users\thecr\AppData\Local\Programs\Python\Python313\Lib\asyncio\base_events.py", line 677, in run_forever
    self._run_once()
  File "C:\Users\thecr\AppData\Local\Programs\Python\Python313\Lib\asyncio\base_events.py", line 2034, in _run_once
    handle._run()
  File "C:\Users\thecr\AppData\Local\Programs\Python\Python313\Lib\asyncio\events.py", line 89, in _run
    self._context.run(self._callback, *self._args)
  File "C:\DreamerAI\main.py", line 90, in run_dreamer_flow
    result = await dreamer_flow.execute(initial_user_input=test_input)
> File "C:\DreamerAI\engine\core\workflow.py", line 86, in execute
    jeff_response = await jeff_agent.run(initial_user_input=initial_user_input) # Changed from guide's user_input to match local var
TypeError: ChefJeff.run() got an unexpected keyword argument 'initial_user_input'. Did you mean 'initial_input'?

Traceback (most recent call last):
  File "C:\DreamerAI\main.py", line 111, in <module>
    asyncio.run(run_dreamer_flow())
  File "C:\Users\thecr\AppData\Local\Programs\Python\Python313\Lib\asyncio\runners.py", line 195, in run
    return runner.run(main)
  File "C:\Users\thecr\AppData\Local\Programs\Python\Python313\Lib\asyncio\runners.py", line 118, in run
    return self._loop.run_until_complete(task)
  File "C:\Users\thecr\AppData\Local\Programs\Python\Python313\Lib\asyncio\base_events.py", line 706, in run_until_complete
    self.run_forever()
  File "C:\Users\thecr\AppData\Local\Programs\Python\Python313\Lib\asyncio\base_events.py", line 677, in run_forever
    self._run_once()
  File "C:\Users\thecr\AppData\Local\Programs\Python\Python313\Lib\asyncio\base_events.py", line 2034, in _run_once
    handle._run()
  File "C:\Users\thecr\AppData\Local\Programs\Python\Python313\Lib\asyncio\events.py", line 89, in _run
    self._context.run(self._callback, *self._args)
  File "C:\DreamerAI\main.py", line 53, in run_dreamer_flow
    agents["Jeff"] = ChefJeff(llm_instance=llm_service, user_dir=DEFAULT_USER_DIR)
  File "C:\DreamerAI\engine\agents\main_chat.py", line 61, in __init__
    super().__init__(name="Jeff", user_dir=data.get("user_dir"), distill=False, llm=llm_instance, **data)
TypeError: engine.agents.base.BaseAgent.__init__() got multiple values for keyword argument 'user_dir'

2025-04-12 00:06:01 | ERROR    | engine.core.workflow:execute:112 - An unexpected error occurred during DreamerFlow execution: ChefJeff.run() got an unexpected keyword argument 'initial_user_input'. Did you mean 'initial_input'?
Traceback (most recent call last):
  File "C:\DreamerAI\main.py", line 111, in <module>
    asyncio.run(run_dreamer_flow())
  File "C:\Users\thecr\AppData\Local\Programs\Python\Python313\Lib\asyncio\runners.py", line 195, in run
    return runner.run(main)
  File "C:\Users\thecr\AppData\Local\Programs\Python\Python313\Lib\asyncio\runners.py", line 118, in run
    return self._loop.run_until_complete(task)
  File "C:\Users\thecr\AppData\Local\Programs\Python\Python313\Lib\asyncio\base_events.py", line 706, in run_until_complete
    self.run_forever()
  File "C:\Users\thecr\AppData\Local\Programs\Python\Python313\Lib\asyncio\base_events.py", line 677, in run_forever
    self._run_once()
  File "C:\Users\thecr\AppData\Local\Programs\Python\Python313\Lib\asyncio\base_events.py", line 2034, in _run_once
    handle._run()
  File "C:\Users\thecr\AppData\Local\Programs\Python\Python313\Lib\asyncio\events.py", line 89, in _run
    self._context.run(self._callback, *self._args)
  File "C:\DreamerAI\main.py", line 90, in run_dreamer_flow
    result = await dreamer_flow.execute(initial_user_input=test_input)
> File "C:\DreamerAI\engine\core\workflow.py", line 86, in execute
    jeff_response = await jeff_agent.run(initial_user_input=initial_user_input) # Changed from guide's user_input to match local var
TypeError: ChefJeff.run() got an unexpected keyword argument 'initial_user_input'. Did you mean 'initial_input'?

Traceback (most recent call last):
  File "C:\DreamerAI\main.py", line 111, in <module>
    asyncio.run(run_dreamer_flow())
  File "C:\Users\thecr\AppData\Local\Programs\Python\Python313\Lib\asyncio\runners.py", line 195, in run
    return runner.run(main)
  File "C:\Users\thecr\AppData\Local\Programs\Python\Python313\Lib\asyncio\runners.py", line 118, in run
    return self._loop.run_until_complete(task)
  File "C:\Users\thecr\AppData\Local\Programs\Python\Python313\Lib\asyncio\base_events.py", line 706, in run_until_complete
    self.run_forever()
  File "C:\Users\thecr\AppData\Local\Programs\Python\Python313\Lib\asyncio\base_events.py", line 677, in run_forever
    self._run_once()
  File "C:\Users\thecr\AppData\Local\Programs\Python\Python313\Lib\asyncio\base_events.py", line 2034, in _run_once
    handle._run()
  File "C:\Users\thecr\AppData\Local\Programs\Python\Python313\Lib\asyncio\events.py", line 89, in _run
    self._context.run(self._callback, *self._args)
  File "C:\DreamerAI\main.py", line 53, in run_dreamer_flow
    agents["Jeff"] = ChefJeff(llm_instance=llm_service, user_dir=DEFAULT_USER_DIR)
  File "C:\DreamerAI\engine\agents\main_chat.py", line 61, in __init__
    super().__init__(name="Jeff", user_dir=data.get("user_dir"), distill=False, llm=llm_instance, **data)
TypeError: engine.agents.base.BaseAgent.__init__() got multiple values for keyword argument 'user_dir'

2025-04-12 00:06:01 | ERROR    | engine.core.workflow:execute:112 - An unexpected error occurred during DreamerFlow execution: ChefJeff.run() got an unexpected keyword argument 'initial_user_input'. Did you mean 'initial_input'?
Traceback (most recent call last):
  File "C:\DreamerAI\main.py", line 111, in <module>
    asyncio.run(run_dreamer_flow())
  File "C:\Users\thecr\AppData\Local\Programs\Python\Python313\Lib\asyncio\runners.py", line 195, in run
    return runner.run(main)
  File "C:\Users\thecr\AppData\Local\Programs\Python\Python313\Lib\asyncio\runners.py", line 118, in run
    return self._loop.run_until_complete(task)
  File "C:\Users\thecr\AppData\Local\Programs\Python\Python313\Lib\asyncio\base_events.py", line 706, in run_until_complete
    self.run